Workbook

Sheet Sheet1
A1: city_name | B1: gdp | C1: region | D1: green_space_and_square | E1: urban_district_population | F1: urban_population | G1: urban_district_temporary_population | H1: c_area | I1: c_water_resources | J1: min_frame_area | K1: max_frame_area | L1: biz | M1: decoration | N1: longitude | O1: latitude | P1: min_frame_rooms | Q1: max_frame_rooms | R1: near_main_road | S1: shopping | T1: bus | U1: equipment | V1: bussiness_circle | W1: built_house | X1: bj_tj | Y1: small_frame | Z1: medicine | AA1: three_jia | AB1: water_scene | AC1: tech_house | AD1: vr | AE1: brand_seller | AF1: metro | AG1: round_line | AH1: greenland | AI1: car_park | AJ1: low_density | AK1: big_block | AL1: veg_market | AM1: mul_trace | AN1: entertain | AO1: snack | AP1: house_type | AQ1: sale_status | AR1: has_short_video | AS1: open_date | AT1: lowest_total_price | AU1: is_cooperation | AV1: reference_unit_price | AW1: reference_lowest_total_price | AX1: reference_highest_total_price | AY1: is_support_online_sale | AZ1: experts_recommend
A2: 保定 | B2: =VLOOKUP(A2,Sheet2!A:G,2,FALSE) -> 3725 | C2: =VLOOKUP(A2,Sheet2!$A:$H,3,FALSE) -> 1 | D2: =VLOOKUP(A2,Sheet4!A:Q,13,FALSE) -> 38.83 | E2: =VLOOKUP(A2,Sheet4!A:C,3,FALSE) -> 289.7 | F2: =VLOOKUP(A2,Sheet4!A:F,6,FALSE) -> 145.60 | G2: =VLOOKUP(A2,Sheet4!A:D,4,FALSE) -> 43.5 | H2: =VLOOKUP(A2,Sheet4!A:H,8,FALSE) -> 206.53 | I2: =VLOOKUP(A2,Sheet2!$A:$H,7,FALSE) -> 262800 | J2: 85 | K2: 128 | L2: 1 | M2: 1 | N2: 116.03671 | O2: 39.530293 | P2: 2 | Q2: 4 | R2: 1 | S2: 0 | T2: 0 | U2: 0 | V2: 0 | W2: 0 | X2: 0 | Y2: 0 | Z2: 0 | AA2: 0 | AB2: 0 | AC2: 0 | AD2: 0 | AE2: 0 | AF2: 0 | AG2: 0 | AH2: 0 | AI2: 0 | AJ2: 0 | AK2: 0 | AL2: 0 | AM2: 0 | AN2: 0 | AO2: 0 | AP2: 0 | AQ2: 0 | AR2: 0 | AS2: 583 | AT2: 900000 | AU2: 2 | AV2: 9000 | AW2: 65 | AX2: 150 | AY2: 1 | AZ2: 0
A3: 保定 | B3: =VLOOKUP(A3,Sheet2!A:G,2,FALSE) -> 3725 | C3: =VLOOKUP(A3,Sheet2!$A:$H,3,FALSE) -> 1 | D3: =VLOOKUP(A3,Sheet4!A:Q,13,FALSE) -> 38.83 | E3: =VLOOKUP(A3,Sheet4!A:C,3,FALSE) -> 289.7 | F3: =VLOOKUP(A3,Sheet4!A:F,6,FALSE) -> 145.60 | G3: =VLOOKUP(A3,Sheet4!A:D,4,FALSE) -> 43.5 | H3: =VLOOKUP(A3,Sheet4!A:H,8,FALSE) -> 206.53 | I3: =VLOOKUP(A3,Sheet2!$A:$H,7,FALSE) -> 262800 | J3: 81 | K3: 119 | L3: 1 | M3: 0 | N3: 116.05976 | O3: 39.472472 | P3: 2 | Q3: 3 | R3: 0 | S3: 0 | T3: 0 | U3: 0 | V3: 1 | W3: 0 | X3: 0 | Y3: 0 | Z3: 0 | AA3: 0 | AB3: 0 | AC3: 0 | AD3: 1 | AE3: 0 | AF3: 0 | AG3: 0 | AH3: 0 | AI3: 0 | AJ3: 0 | AK3: 0 | AL3: 0 | AM3: 1 | AN3: 0 | AO3: 0 | AP3: 0 | AQ3: 0 | AR3: 0 | AS3: 465 | AT3: 680000 | AU3: 2 | AV3: 8500 | AW3: 73 | AX3: 110 | AY3: 1 | AZ3: 0
A4: 保定 | B4: =VLOOKUP(A4,Sheet2!A:G,2,FALSE) -> 3725 | C4: =VLOOKUP(A4,Sheet2!$A:$H,3,FALSE) -> 1 | D4: =VLOOKUP(A4,Sheet4!A:Q,13,FALSE) -> 38.83 | E4: =VLOOKUP(A4,Sheet4!A:C,3,FALSE) -> 289.7 | F4: =VLOOKUP(A4,Sheet4!A:F,6,FALSE) -> 145.60 | G4: =VLOOKUP(A4,Sheet4!A:D,4,FALSE) -> 43.5 | H4: =VLOOKUP(A4,Sheet4!A:H,8,FALSE) -> 206.53 | I4: =VLOOKUP(A4,Sheet2!$A:$H,7,FALSE) -> 262800 | J4: 80 | K4: 121 | L4: 1 | M4: 1 | N4: 115.9992 | O4: 39.476842 | P4: 2 | Q4: 3 | R4: 0 | S4: 0 | T4: 0 | U4: 1 | V4: 1 | W4: 0 | X4: 0 | Y4: 0 | Z4: 0 | AA4: 0 | AB4: 0 | AC4: 0 | AD4: 0 | AE4: 0 | AF4: 0 | AG4: 0 | AH4: 0 | AI4: 0 | AJ4: 0 | AK4: 0 | AL4: 0 | AM4: 0 | AN4: 0 | AO4: 0 | AP4: 0 | AQ4: 0 | AR4: 0 | AS4: 870 | AT4: 640000 | AU4: 2 | AV4: 7900 | AW4: 62 | AX4: 98 | AY4: 0 | AZ4: 0
A5: 保定 | B5: =VLOOKUP(A5,Sheet2!A:G,2,FALSE) -> 3725 | C5: =VLOOKUP(A5,Sheet2!$A:$H,3,FALSE) -> 1 | D5: =VLOOKUP(A5,Sheet4!A:Q,13,FALSE) -> 38.83 | E5: =VLOOKUP(A5,Sheet4!A:C,3,FALSE) -> 289.7 | F5: =VLOOKUP(A5,Sheet4!A:F,6,FALSE) -> 145.60 | G5: =VLOOKUP(A5,Sheet4!A:D,4,FALSE) -> 43.5 | H5: =VLOOKUP(A5,Sheet4!A:H,8,FALSE) -> 206.53 | I5: =VLOOKUP(A5,Sheet2!$A:$H,7,FALSE) -> 262800 | J5: 87 | K5: 145 | L5: 1 | M5: 1 | N5: 116.03589 | O5: 39.475607 | P5: 3 | Q5: 4 | R5: 0 | S5: 1 | T5: 0 | U5: 1 | V5: 0 | W5: 0 | X5: 0 | Y5: 0 | Z5: 1 | AA5: 0 | AB5: 0 | AC5: 0 | AD5: 0 | AE5: 0 | AF5: 0 | AG5: 0 | AH5: 0 | AI5: 0 | AJ5: 0 | AK5: 0 | AL5: 0 | AM5: 0 | AN5: 0 | AO5: 0 | AP5: 0 | AQ5: 0 | AR5: 0 | AS5: 899 | AT5: 720000 | AU5: 2 | AV5: 8500 | AW5: 68 | AX5: 142 | AY5: 0 | AZ5: 0
A6: 保定 | B6: =VLOOKUP(A6,Sheet2!A:G,2,FALSE) -> 3725 | C6: =VLOOKUP(A6,Sheet2!$A:$H,3,FALSE) -> 1 | D6: =VLOOKUP(A6,Sheet4!A:Q,13,FALSE) -> 38.83 | E6: =VLOOKUP(A6,Sheet4!A:C,3,FALSE) -> 289.7 | F6: =VLOOKUP(A6,Sheet4!A:F,6,FALSE) -> 145.60 | G6: =VLOOKUP(A6,Sheet4!A:D,4,FALSE) -> 43.5 | H6: =VLOOKUP(A6,Sheet4!A:H,8,FALSE) -> 206.53 | I6: =VLOOKUP(A6,Sheet2!$A:$H,7,FALSE) -> 262800 | J6: 101 | K6: 125 | L6: 1 | M6: 1 | N6: 116.02219 | O6: 39.583697 | P6: 3 | Q6: 3 | R6: 0 | S6: 1 | T6: 0 | U6: 0 | V6: 0 | W6: 0 | X6: 0 | Y6: 0 | Z6: 1 | AA6: 0 | AB6: 0 | AC6: 0 | AD6: 0 | AE6: 1 | AF6: 0 | AG6: 0 | AH6: 0 | AI6: 0 | AJ6: 0 | AK6: 0 | AL6: 0 | AM6: 0 | AN6: 0 | AO6: 1 | AP6: 0 | AQ6: 0 | AR6: 0 | AS6: 1344 | AT6: 1160000 | AU6: 0 | AV6: 12000 | AW6: 116 | AX6: 164 | AY6: 0 | AZ6: 0
A7: 巴彦淖尔 | B7: 982.7 | C7: 3 | D7: =VLOOKUP(A7,Sheet4!A:Q,13,FALSE) -> 1.24 | E7: =VLOOKUP(A7,Sheet4!A:C,3,FALSE) -> 51.7 | F7: =VLOOKUP(A7,Sheet4!A:F,6,FALSE) -> 32.72 | G7: =VLOOKUP(A7,Sheet4!A:D,4,FALSE) -> 8.2 | H7: =VLOOKUP(A7,Sheet4!A:H,8,FALSE) -> 51.00 | I7: 564990 | J7: 95 | K7: 141 | L7: 0 | M7: 1 | N7: 107.37906 | O7: 40.754896 | P7: 2 | Q7: 3 | R7: 1 | S7: 0 | T7: 0 | U7: 0 | V7: 1 | W7: 0 | X7: 0 | Y7: 0 | Z7: 0 | AA7: 0 | AB7: 0 | AC7: 0 | AD7: 0 | AE7: 0 | AF7: 0 | AG7: 0 | AH7: 0 | AI7: 0 | AJ7: 0 | AK7: 0 | AL7: 0 | AM7: 1 | AN7: 0 | AO7: 0 | AP7: 0 | AQ7: 0 | AR7: 0 | AS7: 1144 | AT7: 800000 | AU7: 2 | AV7: 6200 | AW7: 64 | AX7: 89 | AY7: 0 | AZ7: 0
A8: 巴彦淖尔 | B8: 982.7 | C8: 3 | D8: =VLOOKUP(A8,Sheet4!A:Q,13,FALSE) -> 1.24 | E8: =VLOOKUP(A8,Sheet4!A:C,3,FALSE) -> 51.7 | F8: =VLOOKUP(A8,Sheet4!A:F,6,FALSE) -> 32.72 | G8: =VLOOKUP(A8,Sheet4!A:D,4,FALSE) -> 8.2 | H8: =VLOOKUP(A8,Sheet4!A:H,8,FALSE) -> 51.00 | I8: 564990 | J8: 98 | K8: 139 | L8: 0 | M8: 1 | N8: 107.38285 | O8: 40.750529 | P8: 2 | Q8: 3 | R8: 1 | S8: 0 | T8: 0 | U8: 0 | V8: 1 | W8: 0 | X8: 0 | Y8: 0 | Z8: 0 | AA8: 1 | AB8: 0 | AC8: 0 | AD8: 0 | AE8: 0 | AF8: 0 | AG8: 0 | AH8: 0 | AI8: 0 | AJ8: 0 | AK8: 0 | AL8: 1 | AM8: 0 | AN8: 0 | AO8: 0 | AP8: 0 | AQ8: 0 | AR8: 0 | AS8: 658 | AT8: 800000 | AU8: 2 | AV8: 6200 | AW8: 60.7 | AX8: 86 | AY8: 0 | AZ8: 0
A9: 巴彦淖尔 | B9: 982.7 | C9: 3 | D9: =VLOOKUP(A9,Sheet4!A:Q,13,FALSE) -> 1.24 | E9: =VLOOKUP(A9,Sheet4!A:C,3,FALSE) -> 51.7 | F9: =VLOOKUP(A9,Sheet4!A:F,6,FALSE) -> 32.72 | G9: =VLOOKUP(A9,Sheet4!A:D,4,FALSE) -> 8.2 | H9: =VLOOKUP(A9,Sheet4!A:H,8,FALSE) -> 51.00 | I9: 564990 | J9: 110 | K9: 142 | L9: 1 | M9: 1 | N9: 107.38656 | O9: 40.786798 | P9: 3 | Q9: 3 | R9: 1 | S9: 0 | T9: 0 | U9: 0 | V9: 0 | W9: 0 | X9: 0 | Y9: 0 | Z9: 0 | AA9: 0 | AB9: 0 | AC9: 0 | AD9: 0 | AE9: 0 | AF9: 0 | AG9: 0 | AH9: 0 | AI9: 0 | AJ9: 0 | AK9: 0 | AL9: 0 | AM9: 1 | AN9: 0 | AO9: 0 | AP9: 0 | AQ9: 0 | AR9: 0 | AS9: 1144 | AT9: 420000 | AU9: 2 | AV9: 4500 | AW9: 49.5 | AX9: 63.9 | AY9: 1 | AZ9: 0
A10: 巴彦淖尔 | B10: 982.7 | C10: 3 | D10: =VLOOKUP(A10,Sheet4!A:Q,13,FALSE) -> 1.24 | E10: =VLOOKUP(A10,Sheet4!A:C,3,FALSE) -> 51.7 | F10: =VLOOKUP(A10,Sheet4!A:F,6,FALSE) -> 32.72 | G10: =VLOOKUP(A10,Sheet4!A:D,4,FALSE) -> 8.2 | H10: =VLOOKUP(A10,Sheet4!A:H,8,FALSE) -> 51.00 | I10: 564990 | J10: 82 | K10: 140 | L10: 0 | M10: 1 | N10: 107.35641 | O10: 40.795628 | P10: 2 | Q10: 4 | R10: 1 | S10: 0 | T10: 0 | U10: 0 | V10: 1 | W10: 0 | X10: 0 | Y10: 0 | Z10: 0 | AA10: 0 | AB10: 0 | AC10: 0 | AD10: 0 | AE10: 0 | AF10: 0 | AG10: 0 | AH10: 0 | AI10: 0 | AJ10: 0 | AK10: 0 | AL10: 0 | AM10: 0 | AN10: 0 | AO10: 0 | AP10: 0 | AQ10: 0 | AR10: 0 | AS10: 1693 | AT10: 420000 | AU10: 2 | AV10: 4300 | AW10: 35 | AX10: 61 | AY10: 0 | AZ10: 0
A11: 巴彦淖尔 | B11: 982.7 | C11: 3 | D11: =VLOOKUP(A11,Sheet4!A:Q,13,FALSE) -> 1.24 | E11: =VLOOKUP(A11,Sheet4!A:C,3,FALSE) -> 51.7 | F11: =VLOOKUP(A11,Sheet4!A:F,6,FALSE) -> 32.72 | G11: =VLOOKUP(A11,Sheet4!A:D,4,FALSE) -> 8.2 | H11: =VLOOKUP(A11,Sheet4!A:H,8,FALSE) -> 51.00 | I11: 564990 | J11: 63 | K11: 124 | L11: 1 | M11: 1 | N11: 107.38828 | O11: 40.772314 | P11: 1 | Q11: 3 | R11: 0 | S11: 0 | T11: 0 | U11: 0 | V11: 0 | W11: 0 | X11: 0 | Y11: 1 | Z11: 0 | AA11: 0 | AB11: 0 | AC11: 0 | AD11: 0 | AE11: 0 | AF11: 0 | AG11: 0 | AH11: 0 | AI11: 0 | AJ11: 0 | AK11: 0 | AL11: 0 | AM11: 0 | AN11: 0 | AO11: 0 | AP11: 0 | AQ11: 0 | AR11: 0 | AS11: 1144 | AT11: 520000 | AU11: 2 | AV11: 5200 | AW11: 32.7 | AX11: 64 | AY11: 0 | AZ11: 0
A12: 北海 | B12: =VLOOKUP(A12,Sheet2!A:G,2,FALSE) -> 1504.43 | C12: =VLOOKUP(A12,Sheet2!$A:$H,3,FALSE) -> 5 | D12: =VLOOKUP(A12,Sheet4!A:Q,13,FALSE) -> 7.95 | E12: =VLOOKUP(A12,Sheet4!A:C,3,FALSE) -> 71.8 | F12: =VLOOKUP(A12,Sheet4!A:F,6,FALSE) -> 40.29 | G12: =VLOOKUP(A12,Sheet4!A:D,4,FALSE) -> 30.5 | H12: =VLOOKUP(A12,Sheet4!A:H,8,FALSE) -> 85.98 | I12: =VLOOKUP(A12,Sheet2!$A:$H,7,FALSE) -> 192000 | J12: 56 | K12: 117 | L12: 1 | M12: 0 | N12: 109.18425 | O12: 21.544756 | P12: 1 | Q12: 4 | R12: 0 | S12: 0 | T12: 1 | U12: 0 | V12: 0 | W12: 0 | X12: 0 | Y12: 0 | Z12: 0 | AA12: 0 | AB12: 0 | AC12: 0 | AD12: 0 | AE12: 0 | AF12: 0 | AG12: 0 | AH12: 0 | AI12: 0 | AJ12: 0 | AK12: 0 | AL12: 0 | AM12: 0 | AN12: 0 | AO12: 0 | AP12: 0 | AQ12: 0 | AR12: 1 | AS12: 1236 | AT12: 300000 | AU12: 0 | AV12: 4999 | AW12: 38 | AX12: 73.5 | AY12: 0 | AZ12: 0
A13: 北海 | B13: =VLOOKUP(A13,Sheet2!A:G,2,FALSE) -> 1504.43 | C13: =VLOOKUP(A13,Sheet2!$A:$H,3,FALSE) -> 5 | D13: =VLOOKUP(A13,Sheet4!A:Q,13,FALSE) -> 7.95 | E13: =VLOOKUP(A13,Sheet4!A:C,3,FALSE) -> 71.8 | F13: =VLOOKUP(A13,Sheet4!A:F,6,FALSE) -> 40.29 | G13: =VLOOKUP(A13,Sheet4!A:D,4,FALSE) -> 30.5 | H13: =VLOOKUP(A13,Sheet4!A:H,8,FALSE) -> 85.98 | I13: =VLOOKUP(A13,Sheet2!$A:$H,7,FALSE) -> 192000 | J13: 81 | K13: 128 | L13: 1 | M13: 0 | N13: 109.17751 | O13: 21.485782 | P13: 2 | Q13: 4 | R13: 1 | S13: 0 | T13: 1 | U13: 0 | V13: 0 | W13: 0 | X13: 0 | Y13: 0 | Z13: 0 | AA13: 0 | AB13: 0 | AC13: 0 | AD13: 0 | AE13: 0 | AF13: 0 | AG13: 0 | AH13: 0 | AI13: 0 | AJ13: 0 | AK13: 0 | AL13: 0 | AM13: 0 | AN13: 0 | AO13: 0 | AP13: 0 | AQ13: 0 | AR13: 1 | AS13: 1509 | AT13: 430000 | AU13: 2 | AV13: 4796 | AW13: 43 | AX13: 64 | AY13: 0 | AZ13: 0
A14: 北海 | B14: =VLOOKUP(A14,Sheet2!A:G,2,FALSE) -> 1504.43 | C14: =VLOOKUP(A14,Sheet2!$A:$H,3,FALSE) -> 5 | D14: =VLOOKUP(A14,Sheet4!A:Q,13,FALSE) -> 7.95 | E14: =VLOOKUP(A14,Sheet4!A:C,3,FALSE) -> 71.8 | F14: =VLOOKUP(A14,Sheet4!A:F,6,FALSE) -> 40.29 | G14: =VLOOKUP(A14,Sheet4!A:D,4,FALSE) -> 30.5 | H14: =VLOOKUP(A14,Sheet4!A:H,8,FALSE) -> 85.98 | I14: =VLOOKUP(A14,Sheet2!$A:$H,7,FALSE) -> 192000 | J14: 81 | K14: 128 | L14: 1 | M14: 0 | N14: 109.09718 | O14: 21.459051 | P14: 3 | Q14: 5 | R14: 0 | S14: 0 | T14: 0 | U14: 0 | V14: 0 | W14: 0 | X14: 0 | Y14: 0 | Z14: 0 | AA14: 0 | AB14: 0 | AC14: 0 | AD14: 1 | AE14: 1 | AF14: 0 | AG14: 0 | AH14: 0 | AI14: 0 | AJ14: 0 | AK14: 0 | AL14: 0 | AM14: 0 | AN14: 0 | AO14: 0 | AP14: 0 | AQ14: 0 | AR14: 1 | AS14: 615 | AT14: 450000 | AU14: 2 | AV14: 5600 | AW14: 45 | AX14: 73 | AY14: 0 | AZ14: 0
A15: 北海 | B15: =VLOOKUP(A15,Sheet2!A:G,2,FALSE) -> 1504.43 | C15: =VLOOKUP(A15,Sheet2!$A:$H,3,FALSE) -> 5 | D15: =VLOOKUP(A15,Sheet4!A:Q,13,FALSE) -> 7.95 | E15: =VLOOKUP(A15,Sheet4!A:C,3,FALSE) -> 71.8 | F15: =VLOOKUP(A15,Sheet4!A:F,6,FALSE) -> 40.29 | G15: =VLOOKUP(A15,Sheet4!A:D,4,FALSE) -> 30.5 | H15: =VLOOKUP(A15,Sheet4!A:H,8,FALSE) -> 85.98 | I15: =VLOOKUP(A15,Sheet2!$A:$H,7,FALSE) -> 192000 | J15: 80 | K15: 312 | L15: 1 | M15: 1 | N15: 109.13454 | O15: 21.463175 | P15: 2 | Q15: 5 | R15: 1 | S15: 0 | T15: 0 | U15: 0 | V15: 1 | W15: 0 | X15: 0 | Y15: 0 | Z15: 0 | AA15: 1 | AB15: 0 | AC15: 0 | AD15: 0 | AE15: 0 | AF15: 0 | AG15: 0 | AH15: 0 | AI15: 0 | AJ15: 0 | AK15: 0 | AL15: 0 | AM15: 0 | AN15: 0 | AO15: 0 | AP15: 0 | AQ15: 0 | AR15: 1 | AS15: 1516 | AT15: 580000 | AU15: 0 | AV15: 5200 | AW15: 41.6 | AX15: 180 | AY15: 0 | AZ15: 0
A16: 北海 | B16: =VLOOKUP(A16,Sheet2!A:G,2,FALSE) -> 1504.43 | C16: =VLOOKUP(A16,Sheet2!$A:$H,3,FALSE) -> 5 | D16: =VLOOKUP(A16,Sheet4!A:Q,13,FALSE) -> 7.95 | E16: =VLOOKUP(A16,Sheet4!A:C,3,FALSE) -> 71.8 | F16: =VLOOKUP(A16,Sheet4!A:F,6,FALSE) -> 40.29 | G16: =VLOOKUP(A16,Sheet4!A:D,4,FALSE) -> 30.5 | H16: =VLOOKUP(A16,Sheet4!A:H,8,FALSE) -> 85.98 | I16: =VLOOKUP(A16,Sheet2!$A:$H,7,FALSE) -> 192000 | J16: 89 | K16: 133 | L16: 1 | M16: 1 | N16: 109.09643 | O16: 21.473671 | P16: 2 | Q16: 3 | R16: 0 | S16: 1 | T16: 0 | U16: 1 | V16: 0 | W16: 0 | X16: 0 | Y16: 0 | Z16: 0 | AA16: 0 | AB16: 0 | AC16: 0 | AD16: 0 | AE16: 0 | AF16: 0 | AG16: 0 | AH16: 0 | AI16: 0 | AJ16: 0 | AK16: 0 | AL16: 0 | AM16: 0 | AN16: 0 | AO16: 0 | AP16: 0 | AQ16: 0 | AR16: 1 | AS16: 779 | AT16: 470000 | AU16: 2 | AV16: 5300 | AW16: 54 | AX16: 87 | AY16: 0 | AZ16: 0
A17: 北海 | B17: =VLOOKUP(A17,Sheet2!A:G,2,FALSE) -> 1504.43 | C17: =VLOOKUP(A17,Sheet2!$A:$H,3,FALSE) -> 5 | D17: =VLOOKUP(A17,Sheet4!A:Q,13,FALSE) -> 7.95 | E17: =VLOOKUP(A17,Sheet4!A:C,3,FALSE) -> 71.8 | F17: =VLOOKUP(A17,Sheet4!A:F,6,FALSE) -> 40.29 | G17: =VLOOKUP(A17,Sheet4!A:D,4,FALSE) -> 30.5 | H17: =VLOOKUP(A17,Sheet4!A:H,8,FALSE) -> 85.98 | I17: =VLOOKUP(A17,Sheet2!$A:$H,7,FALSE) -> 192000 | J17: 40 | K17: 76 | L17: 1 | M17: 0 | N17: 109.09954 | O17: 21.447418 | P17: 1 | Q17: 3 | R17: 1 | S17: 0 | T17: 1 | U17: 1 | V17: 0 | W17: 0 | X17: 0 | Y17: 0 | Z17: 0 | AA17: 0 | AB17: 0 | AC17: 0 | AD17: 0 | AE17: 0 | AF17: 0 | AG17: 0 | AH17: 0 | AI17: 0 | AJ17: 0 | AK17: 0 | AL17: 0 | AM17: 0 | AN17: 0 | AO17: 0 | AP17: 0 | AQ17: 0 | AR17: 1 | AS17: 1533 | AT17: 350000 | AU17: 2 | AV17: 8200 | AW17: 33 | AX17: 82 | AY17: 0 | AZ17: 0
A18: 北海 | B18: =VLOOKUP(A18,Sheet2!A:G,2,FALSE) -> 1504.43 | C18: =VLOOKUP(A18,Sheet2!$A:$H,3,FALSE) -> 5 | D18: =VLOOKUP(A18,Sheet4!A:Q,13,FALSE) -> 7.95 | E18: =VLOOKUP(A18,Sheet4!A:C,3,FALSE) -> 71.8 | F18: =VLOOKUP(A18,Sheet4!A:F,6,FALSE) -> 40.29 | G18: =VLOOKUP(A18,Sheet4!A:D,4,FALSE) -> 30.5 | H18: =VLOOKUP(A18,Sheet4!A:H,8,FALSE) -> 85.98 | I18: =VLOOKUP(A18,Sheet2!$A:$H,7,FALSE) -> 192000 | J18: 50 | K18: 100 | L18: 1 | M18: 0 | N18: 109.16712 | O18: 21.428873 | P18: 1 | Q18: 3 | R18: 1 | S18: 1 | T18: 1 | U18: 0 | V18: 1 | W18: 0 | X18: 0 | Y18: 0 | Z18: 0 | AA18: 0 | AB18: 0 | AC18: 0 | AD18: 0 | AE18: 0 | AF18: 0 | AG18: 0 | AH18: 0 | AI18: 0 | AJ18: 0 | AK18: 0 | AL18: 0 | AM18: 0 | AN18: 0 | AO18: 0 | AP18: 0 | AQ18: 0 | AR18: 1 | AS18: 1423 | AT18: 750000 | AU18: 0 | AV18: 10000 | AW18: 57 | AX18: 130 | AY18: 0 | AZ18: 0
A19: 北海 | B19: =VLOOKUP(A19,Sheet2!A:G,2,FALSE) -> 1504.43 | C19: =VLOOKUP(A19,Sheet2!$A:$H,3,FALSE) -> 5 | D19: =VLOOKUP(A19,Sheet4!A:Q,13,FALSE) -> 7.95 | E19: =VLOOKUP(A19,Sheet4!A:C,3,FALSE) -> 71.8 | F19: =VLOOKUP(A19,Sheet4!A:F,6,FALSE) -> 40.29 | G19: =VLOOKUP(A19,Sheet4!A:D,4,FALSE) -> 30.5 | H19: =VLOOKUP(A19,Sheet4!A:H,8,FALSE) -> 85.98 | I19: =VLOOKUP(A19,Sheet2!$A:$H,7,FALSE) -> 192000 | J19: 79 | K19: 121 | L19: 1 | M19: 0 | N19: 109.14781 | O19: 21.500189 | P19: 2 | Q19: 3 | R19: 0 | S19: 1 | T19: 1 | U19: 1 | V19: 0 | W19: 0 | X19: 0 | Y19: 0 | Z19: 0 | AA19: 0 | AB19: 0 | AC19: 0 | AD19: 0 | AE19: 0 | AF19: 0 | AG19: 0 | AH19: 0 | AI19: 0 | AJ19: 0 | AK19: 0 | AL19: 0 | AM19: 0 | AN19: 0 | AO19: 0 | AP19: 0 | AQ19: 0 | AR19: 0 | AS19: 1449 | AT19: 890000 | AU19: 2 | AV19: 11000 | AW19: 90 | AX19: 157 | AY19: 0 | AZ19: 0
A20: 北海 | B20: =VLOOKUP(A20,Sheet2!A:G,2,FALSE) -> 1504.43 | C20: =VLOOKUP(A20,Sheet2!$A:$H,3,FALSE) -> 5 | D20: =VLOOKUP(A20,Sheet4!A:Q,13,FALSE) -> 7.95 | E20: =VLOOKUP(A20,Sheet4!A:C,3,FALSE) -> 71.8 | F20: =VLOOKUP(A20,Sheet4!A:F,6,FALSE) -> 40.29 | G20: =VLOOKUP(A20,Sheet4!A:D,4,FALSE) -> 30.5 | H20: =VLOOKUP(A20,Sheet4!A:H,8,FALSE) -> 85.98 | I20: =VLOOKUP(A20,Sheet2!$A:$H,7,FALSE) -> 192000 | J20: 55 | K20: 139 | L20: 1 | M20: 1 | N20: 109.10086 | O20: 21.44504 | P20: 1 | Q20: 3 | R20: 1 | S20: 0 | T20: 0 | U20: 1 | V20: 0 | W20: 0 | X20: 0 | Y20: 0 | Z20: 0 | AA20: 0 | AB20: 0 | AC20: 0 | AD20: 0 | AE20: 0 | AF20: 0 | AG20: 0 | AH20: 0 | AI20: 0 | AJ20: 0 | AK20: 0 | AL20: 0 | AM20: 0 | AN20: 0 | AO20: 0 | AP20: 0 | AQ20: 0 | AR20: 1 | AS20: 1480 | AT20: 450000 | AU20: 0 | AV20: 5300 | AW20: 31 | AX20: 100 | AY20: 0 | AZ20: 0
A21: 北京 | B21: =VLOOKUP(A21,Sheet2!A:G,2,FALSE) -> 40269.55 | C21: =VLOOKUP(A21,Sheet2!$A:$H,3,FALSE) -> 1 | D21: 116.24 | E21: =VLOOKUP(A21,Sheet4!A:C,3,FALSE) -> 2188.6 | F21: =VLOOKUP(A21,Sheet4!A:F,6,FALSE) -> 1916.10 | G21: 841.8 | H21: 149.05 | I21: =VLOOKUP(A21,Sheet2!$A:$H,7,FALSE) -> 257600 | J21: 220 | K21: 260 | L21: 0 | M21: 1 | N21: 117.20675 | O21: 40.118125 | P21: 3 | Q21: 3 | R21: 0 | S21: 0 | T21: 0 | U21: 0 | V21: 0 | W21: 0 | X21: 0 | Y21: 0 | Z21: 0 | AA21: 0 | AB21: 0 | AC21: 0 | AD21: 0 | AE21: 0 | AF21: 0 | AG21: 1 | AH21: 0 | AI21: 0 | AJ21: 0 | AK21: 0 | AL21: 0 | AM21: 0 | AN21: 0 | AO21: 0 | AP21: 1 | AQ21: 0 | AR21: 1 | AS21: 1672 | AT21: 3650000 | AU21: 2 | AV21: 16000 | AW21: 300 | AX21: 380 | AY21: 0 | AZ21: 0
A22: 北京 | B22: =VLOOKUP(A22,Sheet2!A:G,2,FALSE) -> 40269.55 | C22: =VLOOKUP(A22,Sheet2!$A:$H,3,FALSE) -> 1 | D22: 116.24 | E22: =VLOOKUP(A22,Sheet4!A:C,3,FALSE) -> 2188.6 | F22: =VLOOKUP(A22,Sheet4!A:F,6,FALSE) -> 1916.10 | G22: 841.8 | H22: 149.05 | I22: =VLOOKUP(A22,Sheet2!$A:$H,7,FALSE) -> 257600 | J22: 185 | K22: 199 | L22: 0 | M22: 1 | N22: 116.16326 | O22: 39.726111 | P22: 3 | Q22: 4 | R22: 0 | S22: 0 | T22: 0 | U22: 0 | V22: 0 | W22: 0 | X22: 0 | Y22: 0 | Z22: 0 | AA22: 0 | AB22: 0 | AC22: 0 | AD22: 0 | AE22: 0 | AF22: 1 | AG22: 1 | AH22: 0 | AI22: 0 | AJ22: 0 | AK22: 0 | AL22: 0 | AM22: 0 | AN22: 0 | AO22: 0 | AP22: 1 | AQ22: 0 | AR22: 1 | AS22: 1663 | AT22: 11000000 | AU22: 2 | AV22: 58000 | AW22: 1100 | AX22: 1300 | AY22: 0 | AZ22: 0
A23: 北京 | B23: =VLOOKUP(A23,Sheet2!A:G,2,FALSE) -> 40269.55 | C23: =VLOOKUP(A23,Sheet2!$A:$H,3,FALSE) -> 1 | D23: 116.24 | E23: =VLOOKUP(A23,Sheet4!A:C,3,FALSE) -> 2188.6 | F23: =VLOOKUP(A23,Sheet4!A:F,6,FALSE) -> 1916.10 | G23: 841.8 | H23: 149.05 | I23: =VLOOKUP(A23,Sheet2!$A:$H,7,FALSE) -> 257600 | J23: 107 | K23: 360 | L23: 0 | M23: 0 | N23: 116.5124 | O23: 40.217544 | P23: 2 | Q23: 5 | R23: 0 | S23: 0 | T23: 0 | U23: 0 | V23: 0 | W23: 0 | X23: 0 | Y23: 0 | Z23: 0 | AA23: 0 | AB23: 0 | AC23: 0 | AD23: 0 | AE23: 0 | AF23: 0 | AG23: 1 | AH23: 0 | AI23: 0 | AJ23: 0 | AK23: 0 | AL23: 0 | AM23: 0 | AN23: 0 | AO23: 0 | AP23: 2 | AQ23: 0 | AR23: 0 | AS23: 2492 | AT23: 2980000 | AU23: 2 | AV23: 27000 | AW23: 410 | AX23: 1690 | AY23: 0 | AZ23: 0
A24: 北京 | B24: =VLOOKUP(A24,Sheet2!A:G,2,FALSE) -> 40269.55 | C24: =VLOOKUP(A24,Sheet2!$A:$H,3,FALSE) -> 1 | D24: 116.24 | E24: =VLOOKUP(A24,Sheet4!A:C,3,FALSE) -> 2188.6 | F24: =VLOOKUP(A24,Sheet4!A:F,6,FALSE) -> 1916.10 | G24: 841.8 | H24: 149.05 | I24: =VLOOKUP(A24,Sheet2!$A:$H,7,FALSE) -> 257600 | J24: 100 | K24: 166 | L24: 0 | M24: 0 | N24: 116.6583 | O24: 39.956566 | P24: 2 | Q24: 4 | R24: 0 | S24: 0 | T24: 1 | U24: 0 | V24: 0 | W24: 0 | X24: 0 | Y24: 0 | Z24: 0 | AA24: 0 | AB24: 0 | AC24: 0 | AD24: 0 | AE24: 0 | AF24: 0 | AG24: 1 | AH24: 0 | AI24: 0 | AJ24: 0 | AK24: 0 | AL24: 0 | AM24: 0 | AN24: 0 | AO24: 0 | AP24: 0 | AQ24: 0 | AR24: 1 | AS24: 1266 | AT24: 4900000 | AU24: 2 | AV24: 49000 | AW24: 500 | AX24: 960 | AY24: 1 | AZ24: 0
A25: 北京 | B25: =VLOOKUP(A25,Sheet2!A:G,2,FALSE) -> 40269.55 | C25: =VLOOKUP(A25,Sheet2!$A:$H,3,FALSE) -> 1 | D25: 116.24 | E25: =VLOOKUP(A25,Sheet4!A:C,3,FALSE) -> 2188.6 | F25: =VLOOKUP(A25,Sheet4!A:F,6,FALSE) -> 1916.10 | G25: 841.8 | H25: 149.05 | I25: =VLOOKUP(A25,Sheet2!$A:$H,7,FALSE) -> 257600 | J25: 166 | K25: 228 | L25: 0 | M25: 0 | N25: 116.20045 | O25: 39.725154 | P25: 3 | Q25: 4 | R25: 0 | S25: 1 | T25: 0 | U25: 0 | V25: 1 | W25: 0 | X25: 0 | Y25: 0 | Z25: 0 | AA25: 0 | AB25: 0 | AC25: 0 | AD25: 0 | AE25: 0 | AF25: 0 | AG25: 0 | AH25: 0 | AI25: 0 | AJ25: 0 | AK25: 0 | AL25: 0 | AM25: 0 | AN25: 0 | AO25: 0 | AP25: 0 | AQ25: 0 | AR25: 1 | AS25: 1834 | AT25: 8400000 | AU25: 2 | AV25: 50000 | AW25: 830 | AX25: 1300 | AY25: 0 | AZ25: 0
A26: 北京 | B26: =VLOOKUP(A26,Sheet2!A:G,2,FALSE) -> 40269.55 | C26: =VLOOKUP(A26,Sheet2!$A:$H,3,FALSE) -> 1 | D26: 116.24 | E26: =VLOOKUP(A26,Sheet4!A:C,3,FALSE) -> 2188.6 | F26: =VLOOKUP(A26,Sheet4!A:F,6,FALSE) -> 1916.10 | G26: 841.8 | H26: 149.05 | I26: =VLOOKUP(A26,Sheet2!$A:$H,7,FALSE) -> 257600 | J26: 45 | K26: 95 | L26: 0 | M26: 0 | N26: 116.36475 | O26: 39.775778 | P26: 1 | Q26: 3 | R26: 0 | S26: 0 | T26: 1 | U26: 1 | V26: 0 | W26: 0 | X26: 0 | Y26: 0 | Z26: 0 | AA26: 0 | AB26: 0 | AC26: 0 | AD26: 0 | AE26: 0 | AF26: 0 | AG26: 1 | AH26: 0 | AI26: 0 | AJ26: 0 | AK26: 0 | AL26: 0 | AM26: 0 | AN26: 0 | AO26: 0 | AP26: 2 | AQ26: 0 | AR26: 0 | AS26: 1754 | AT26: 2200000 | AU26: 2 | AV26: 27000 | AW26: 122 | AX26: 258 | AY26: 0 | AZ26: 0
A27: 北京 | B27: =VLOOKUP(A27,Sheet2!A:G,2,FALSE) -> 40269.55 | C27: =VLOOKUP(A27,Sheet2!$A:$H,3,FALSE) -> 1 | D27: 116.24 | E27: =VLOOKUP(A27,Sheet4!A:C,3,FALSE) -> 2188.6 | F27: =VLOOKUP(A27,Sheet4!A:F,6,FALSE) -> 1916.10 | G27: 841.8 | H27: 149.05 | I27: =VLOOKUP(A27,Sheet2!$A:$H,7,FALSE) -> 257600 | J27: 300 | K27: 536 | L27: 0 | M27: 1 | N27: 116.38862 | O27: 40.192075 | P27: 4 | Q27: 5 | R27: 1 | S27: 0 | T27: 0 | U27: 0 | V27: 0 | W27: 0 | X27: 0 | Y27: 0 | Z27: 0 | AA27: 0 | AB27: 0 | AC27: 0 | AD27: 0 | AE27: 0 | AF27: 0 | AG27: 1 | AH27: 0 | AI27: 0 | AJ27: 0 | AK27: 0 | AL27: 0 | AM27: 0 | AN27: 0 | AO27: 0 | AP27: 1 | AQ27: 0 | AR27: 1 | AS27: 2394 | AT27: 20000000 | AU27: 2 | AV27: 40000 | AW27: 1966 | AX27: 8800 | AY27: 0 | AZ27: 0
A28: 北京 | B28: =VLOOKUP(A28,Sheet2!A:G,2,FALSE) -> 40269.55 | C28: =VLOOKUP(A28,Sheet2!$A:$H,3,FALSE) -> 1 | D28: 116.24 | E28: =VLOOKUP(A28,Sheet4!A:C,3,FALSE) -> 2188.6 | F28: =VLOOKUP(A28,Sheet4!A:F,6,FALSE) -> 1916.10 | G28: 841.8 | H28: 149.05 | I28: =VLOOKUP(A28,Sheet2!$A:$H,7,FALSE) -> 257600 | J28: 115 | K28: 293 | L28: 0 | M28: 1 | N28: 116.17358 | O28: 39.769564 | P28: 3 | Q28: 5 | R28: 0 | S28: 0 | T28: 0 | U28: 1 | V28: 0 | W28: 0 | X28: 0 | Y28: 0 | Z28: 0 | AA28: 0 | AB28: 0 | AC28: 0 | AD28: 0 | AE28: 0 | AF28: 0 | AG28: 1 | AH28: 0 | AI28: 0 | AJ28: 0 | AK28: 0 | AL28: 0 | AM28: 1 | AN28: 0 | AO28: 0 | AP28: 0 | AQ28: 0 | AR28: 1 | AS28: 1428 | AT28: 4800000 | AU28: 2 | AV28: 38000 | AW28: 420 | AX28: 1000 | AY28: 0 | AZ28: 0
A29: 北京 | B29: =VLOOKUP(A29,Sheet2!A:G,2,FALSE) -> 40269.55 | C29: =VLOOKUP(A29,Sheet2!$A:$H,3,FALSE) -> 1 | D29: 116.24 | E29: =VLOOKUP(A29,Sheet4!A:C,3,FALSE) -> 2188.6 | F29: =VLOOKUP(A29,Sheet4!A:F,6,FALSE) -> 1916.10 | G29: 841.8 | H29: 149.05 | I29: =VLOOKUP(A29,Sheet2!$A:$H,7,FALSE) -> 257600 | J29: 208 | K29: 320 | L29: 0 | M29: 1 | N29: 116.06243 | O29: 39.884959 | P29: 3 | Q29: 4 | R29: 0 | S29: 0 | T29: 1 | U29: 0 | V29: 0 | W29: 0 | X29: 0 | Y29: 0 | Z29: 0 | AA29: 0 | AB29: 0 | AC29: 0 | AD29: 0 | AE29: 0 | AF29: 0 | AG29: 0 | AH29: 0 | AI29: 0 | AJ29: 0 | AK29: 0 | AL29: 0 | AM29: 1 | AN29: 0 | AO29: 0 | AP29: 1 | AQ29: 0 | AR29: 1 | AS29: 1869 | AT29: 14000000 | AU29: 2 | AV29: 45000 | AW29: 1250 | AX29: 1870 | AY29: 1 | AZ29: 0
A30: 北京 | B30: =VLOOKUP(A30,Sheet2!A:G,2,FALSE) -> 40269.55 | C30: =VLOOKUP(A30,Sheet2!$A:$H,3,FALSE) -> 1 | D30: 116.24 | E30: =VLOOKUP(A30,Sheet4!A:C,3,FALSE) -> 2188.6 | F30: =VLOOKUP(A30,Sheet4!A:F,6,FALSE) -> 1916.10 | G30: 841.8 | H30: 149.05 | I30: =VLOOKUP(A30,Sheet2!$A:$H,7,FALSE) -> 257600 | J30: 290 | K30: 330 | L30: 0 | M30: 1 | N30: 116.17126 | O30: 39.743572 | P30: 3 | Q30: 5 | R30: 0 | S30: 0 | T30: 1 | U30: 1 | V30: 0 | W30: 0 | X30: 0 | Y30: 0 | Z30: 0 | AA30: 0 | AB30: 0 | AC30: 0 | AD30: 0 | AE30: 0 | AF30: 1 | AG30: 0 | AH30: 0 | AI30: 0 | AJ30: 0 | AK30: 0 | AL30: 0 | AM30: 0 | AN30: 0 | AO30: 0 | AP30: 1 | AQ30: 0 | AR30: 1 | AS30: 2058 | AT30: 12500000 | AU30: 2 | AV30: 40000 | AW30: 1150 | AX30: 1400 | AY30: 1 | AZ30: 0
A31: 长春 | B31: =VLOOKUP(A31,Sheet2!A:G,2,FALSE) -> 7103.1 | C31: =VLOOKUP(A31,Sheet2!$A:$H,3,FALSE) -> 0 | D31: =VLOOKUP(A31,Sheet4!A:Q,13,FALSE) -> 133.47 | E31: =VLOOKUP(A31,Sheet4!A:C,3,FALSE) -> 447.4 | F31: =VLOOKUP(A31,Sheet4!A:F,6,FALSE) -> 364.67 | G31: =VLOOKUP(A31,Sheet4!A:D,4,FALSE) -> 125.8 | H31: =VLOOKUP(A31,Sheet4!A:H,8,FALSE) -> 562.42 | I31: =VLOOKUP(A31,Sheet2!$A:$H,7,FALSE) -> 514593 | J31: 82 | K31: 119 | L31: 0 | M31: 1 | N31: 125.24502 | O31: 44.008173 | P31: 2 | Q31: 3 | R31: 1 | S31: 1 | T31: 1 | U31: 0 | V31: 0 | W31: 0 | X31: 0 | Y31: 0 | Z31: 0 | AA31: 0 | AB31: 0 | AC31: 0 | AD31: 0 | AE31: 0 | AF31: 0 | AG31: 0 | AH31: 0 | AI31: 0 | AJ31: 0 | AK31: 0 | AL31: 0 | AM31: 0 | AN31: 0 | AO31: 1 | AP31: 0 | AQ31: 0 | AR31: 1 | AS31: 1370 | AT31: 700000 | AU31: 0 | AV31: 8500 | AW31: 69 | AX31: =AW31+60 -> 129 | AY31: 0 | AZ31: 0
A32: 长春 | B32: =VLOOKUP(A32,Sheet2!A:G,2,FALSE) -> 7103.1 | C32: =VLOOKUP(A32,Sheet2!$A:$H,3,FALSE) -> 0 | D32: =VLOOKUP(A32,Sheet4!A:Q,13,FALSE) -> 133.47 | E32: =VLOOKUP(A32,Sheet4!A:C,3,FALSE) -> 447.4 | F32: =VLOOKUP(A32,Sheet4!A:F,6,FALSE) -> 364.67 | G32: =VLOOKUP(A32,Sheet4!A:D,4,FALSE) -> 125.8 | H32: =VLOOKUP(A32,Sheet4!A:H,8,FALSE) -> 562.42 | I32: =VLOOKUP(A32,Sheet2!$A:$H,7,FALSE) -> 514593 | J32: 78 | K32: 139 | L32: 0 | M32: 1 | N32: 125.18357 | O32: 44.081683 | P32: 2 | Q32: 3 | R32: 0 | S32: 1 | T32: 0 | U32: 0 | V32: 1 | W32: 0 | X32: 0 | Y32: 0 | Z32: 1 | AA32: 0 | AB32: 0 | AC32: 0 | AD32: 0 | AE32: 0 | AF32: 0 | AG32: 0 | AH32: 0 | AI32: 0 | AJ32: 0 | AK32: 0 | AL32: 0 | AM32: 0 | AN32: 0 | AO32: 0 | AP32: 0 | AQ32: 0 | AR32: 0 | AS32: 1467 | AT32: 440000 | AU32: 0 | AV32: 5100 | AW32: 33.81 | AX32: 61 | AY32: 0 | AZ32: 0
A33: 长春 | B33: =VLOOKUP(A33,Sheet2!A:G,2,FALSE) -> 7103.1 | C33: =VLOOKUP(A33,Sheet2!$A:$H,3,FALSE) -> 0 | D33: =VLOOKUP(A33,Sheet4!A:Q,13,FALSE) -> 133.47 | E33: =VLOOKUP(A33,Sheet4!A:C,3,FALSE) -> 447.4 | F33: =VLOOKUP(A33,Sheet4!A:F,6,FALSE) -> 364.67 | G33: =VLOOKUP(A33,Sheet4!A:D,4,FALSE) -> 125.8 | H33: =VLOOKUP(A33,Sheet4!A:H,8,FALSE) -> 562.42 | I33: =VLOOKUP(A33,Sheet2!$A:$H,7,FALSE) -> 514593 | J33: 83 | K33: 83 | L33: 0 | M33: 1 | N33: 125.26503 | O33: 44.017641 | P33: 2 | Q33: 2 | R33: 1 | S33: 0 | T33: 1 | U33: 0 | V33: 0 | W33: 0 | X33: 0 | Y33: 0 | Z33: 0 | AA33: 0 | AB33: 0 | AC33: 0 | AD33: 0 | AE33: 0 | AF33: 0 | AG33: 0 | AH33: 0 | AI33: 0 | AJ33: 0 | AK33: 0 | AL33: 0 | AM33: 0 | AN33: 0 | AO33: 0 | AP33: 0 | AQ33: 0 | AR33: 1 | AS33: 1002 | AT33: 610000 | AU33: 0 | AV33: 7300 | AW33: 63 | AX33: =AW33+60 -> 123 | AY33: 0 | AZ33: 0
A34: 长春 | B34: =VLOOKUP(A34,Sheet2!A:G,2,FALSE) -> 7103.1 | C34: =VLOOKUP(A34,Sheet2!$A:$H,3,FALSE) -> 0 | D34: =VLOOKUP(A34,Sheet4!A:Q,13,FALSE) -> 133.47 | E34: =VLOOKUP(A34,Sheet4!A:C,3,FALSE) -> 447.4 | F34: =VLOOKUP(A34,Sheet4!A:F,6,FALSE) -> 364.67 | G34: =VLOOKUP(A34,Sheet4!A:D,4,FALSE) -> 125.8 | H34: =VLOOKUP(A34,Sheet4!A:H,8,FALSE) -> 562.42 | I34: =VLOOKUP(A34,Sheet2!$A:$H,7,FALSE) -> 514593 | J34: 118 | K34: 156 | L34: 1 | M34: 1 | N34: 125.42528 | O34: 43.778276 | P34: 1 | Q34: 3 | R34: 0 | S34: 1 | T34: 0 | U34: 0 | V34: 0 | W34: 0 | X34: 0 | Y34: 0 | Z34: 1 | AA34: 0 | AB34: 0 | AC34: 0 | AD34: 0 | AE34: 1 | AF34: 0 | AG34: 0 | AH34: 0 | AI34: 0 | AJ34: 0 | AK34: 0 | AL34: 0 | AM34: 0 | AN34: 1 | AO34: 0 | AP34: 0 | AQ34: 0 | AR34: 0 | AS34: 1611 | AT34: 1200000 | AU34: 0 | AV34: 12500 | AW34: 120 | AX34: 156 | AY34: 0 | AZ34: 0
A35: 长春 | B35: =VLOOKUP(A35,Sheet2!A:G,2,FALSE) -> 7103.1 | C35: =VLOOKUP(A35,Sheet2!$A:$H,3,FALSE) -> 0 | D35: =VLOOKUP(A35,Sheet4!A:Q,13,FALSE) -> 133.47 | E35: =VLOOKUP(A35,Sheet4!A:C,3,FALSE) -> 447.4 | F35: =VLOOKUP(A35,Sheet4!A:F,6,FALSE) -> 364.67 | G35: =VLOOKUP(A35,Sheet4!A:D,4,FALSE) -> 125.8 | H35: =VLOOKUP(A35,Sheet4!A:H,8,FALSE) -> 562.42 | I35: =VLOOKUP(A35,Sheet2!$A:$H,7,FALSE) -> 514593 | J35: 70 | K35: 154 | L35: 0 | M35: 1 | N35: 125.39104 | O35: 43.927696 | P35: 2 | Q35: 4 | R35: 1 | S35: 0 | T35: 1 | U35: 0 | V35: 1 | W35: 0 | X35: 0 | Y35: 0 | Z35: 0 | AA35: 0 | AB35: 0 | AC35: 0 | AD35: 0 | AE35: 0 | AF35: 0 | AG35: 0 | AH35: 0 | AI35: 0 | AJ35: 0 | AK35: 0 | AL35: 1 | AM35: 0 | AN35: 0 | AO35: 0 | AP35: 0 | AQ35: 0 | AR35: 1 | AS35: 992 | AT35: 740000 | AU35: 2 | AV35: 8000 | AW35: 63 | AX35: 140 | AY35: 0 | AZ35: 0
A36: 长春 | B36: =VLOOKUP(A36,Sheet2!A:G,2,FALSE) -> 7103.1 | C36: =VLOOKUP(A36,Sheet2!$A:$H,3,FALSE) -> 0 | D36: =VLOOKUP(A36,Sheet4!A:Q,13,FALSE) -> 133.47 | E36: =VLOOKUP(A36,Sheet4!A:C,3,FALSE) -> 447.4 | F36: =VLOOKUP(A36,Sheet4!A:F,6,FALSE) -> 364.67 | G36: =VLOOKUP(A36,Sheet4!A:D,4,FALSE) -> 125.8 | H36: =VLOOKUP(A36,Sheet4!A:H,8,FALSE) -> 562.42 | I36: =VLOOKUP(A36,Sheet2!$A:$H,7,FALSE) -> 514593 | J36: 88 | K36: 128 | L36: 0 | M36: 0 | N36: 125.36396 | O36: 43.914998 | P36: 2 | Q36: 3 | R36: 0 | S36: 0 | T36: 0 | U36: 0 | V36: 1 | W36: 0 | X36: 0 | Y36: 0 | Z36: 0 | AA36: 0 | AB36: 0 | AC36: 0 | AD36: 0 | AE36: 0 | AF36: 1 | AG36: 0 | AH36: 0 | AI36: 0 | AJ36: 0 | AK36: 0 | AL36: 0 | AM36: 1 | AN36: 0 | AO36: 0 | AP36: 0 | AQ36: 0 | AR36: 1 | AS36: 960 | AT36: 1300000 | AU36: 2 | AV36: 12000 | AW36: 110 | AX36: 130 | AY36: 0 | AZ36: 0
A37: 长春 | B37: =VLOOKUP(A37,Sheet2!A:G,2,FALSE) -> 7103.1 | C37: =VLOOKUP(A37,Sheet2!$A:$H,3,FALSE) -> 0 | D37: =VLOOKUP(A37,Sheet4!A:Q,13,FALSE) -> 133.47 | E37: =VLOOKUP(A37,Sheet4!A:C,3,FALSE) -> 447.4 | F37: =VLOOKUP(A37,Sheet4!A:F,6,FALSE) -> 364.67 | G37: =VLOOKUP(A37,Sheet4!A:D,4,FALSE) -> 125.8 | H37: =VLOOKUP(A37,Sheet4!A:H,8,FALSE) -> 562.42 | I37: =VLOOKUP(A37,Sheet2!$A:$H,7,FALSE) -> 514593 | J37: 345 | K37: 370 | L37: 1 | M37: 1 | N37: 125.41094 | O37: 43.771293 | P37: 5 | Q37: 5 | R37: 1 | S37: 1 | T37: 0 | U37: 0 | V37: 0 | W37: 0 | X37: 0 | Y37: 0 | Z37: 1 | AA37: 0 | AB37: 0 | AC37: 0 | AD37: 0 | AE37: 0 | AF37: 0 | AG37: 0 | AH37: 0 | AI37: 0 | AJ37: 0 | AK37: 0 | AL37: 0 | AM37: 0 | AN37: 1 | AO37: 0 | AP37: 1 | AQ37: 0 | AR37: 0 | AS37: 1554 | AT37: 5500000 | AU37: 0 | AV37: 16000 | AW37: 500 | AX37: =AW37+60 -> 560 | AY37: 0 | AZ37: 0
A38: 长春 | B38: =VLOOKUP(A38,Sheet2!A:G,2,FALSE) -> 7103.1 | C38: =VLOOKUP(A38,Sheet2!$A:$H,3,FALSE) -> 0 | D38: =VLOOKUP(A38,Sheet4!A:Q,13,FALSE) -> 133.47 | E38: =VLOOKUP(A38,Sheet4!A:C,3,FALSE) -> 447.4 | F38: =VLOOKUP(A38,Sheet4!A:F,6,FALSE) -> 364.67 | G38: =VLOOKUP(A38,Sheet4!A:D,4,FALSE) -> 125.8 | H38: =VLOOKUP(A38,Sheet4!A:H,8,FALSE) -> 562.42 | I38: =VLOOKUP(A38,Sheet2!$A:$H,7,FALSE) -> 514593 | J38: 108 | K38: 147 | L38: 0 | M38: 0 | N38: 125.40355 | O38: 43.980534 | P38: 3 | Q38: 3 | R38: 1 | S38: 1 | T38: 1 | U38: 0 | V38: 0 | W38: 0 | X38: 0 | Y38: 0 | Z38: 0 | AA38: 0 | AB38: 0 | AC38: 0 | AD38: 0 | AE38: 0 | AF38: 0 | AG38: 0 | AH38: 0 | AI38: 0 | AJ38: 0 | AK38: 0 | AL38: 0 | AM38: 0 | AN38: 1 | AO38: 0 | AP38: 0 | AQ38: 0 | AR38: 1 | AS38: 1451 | AT38: 1250000 | AU38: 0 | AV38: 10500 | AW38: 123 | AX38: =AW38+60 -> 183 | AY38: 0 | AZ38: 0
A39: 长春 | B39: =VLOOKUP(A39,Sheet2!A:G,2,FALSE) -> 7103.1 | C39: =VLOOKUP(A39,Sheet2!$A:$H,3,FALSE) -> 0 | D39: =VLOOKUP(A39,Sheet4!A:Q,13,FALSE) -> 133.47 | E39: =VLOOKUP(A39,Sheet4!A:C,3,FALSE) -> 447.4 | F39: =VLOOKUP(A39,Sheet4!A:F,6,FALSE) -> 364.67 | G39: =VLOOKUP(A39,Sheet4!A:D,4,FALSE) -> 125.8 | H39: =VLOOKUP(A39,Sheet4!A:H,8,FALSE) -> 562.42 | I39: =VLOOKUP(A39,Sheet2!$A:$H,7,FALSE) -> 514593 | J39: 115 | K39: 149 | L39: 1 | M39: 0 | N39: 125.39142 | O39: 43.828758 | P39: 3 | Q39: 4 | R39: 1 | S39: 1 | T39: 0 | U39: 1 | V39: 0 | W39: 0 | X39: 0 | Y39: 0 | Z39: 1 | AA39: 0 | AB39: 0 | AC39: 0 | AD39: 0 | AE39: 0 | AF39: 0 | AG39: 0 | AH39: 0 | AI39: 0 | AJ39: 0 | AK39: 0 | AL39: 0 | AM39: 0 | AN39: 0 | AO39: 0 | AP39: 0 | AQ39: 0 | AR39: 1 | AS39: 863 | AT39: 1300000 | AU39: 2 | AV39: 12000 | AW39: 130 | AX39: =AW39+60 -> 190 | AY39: 0 | AZ39: 0
A40: 滁州 | B40: 3362.1 | C40: 2 | D40: =VLOOKUP(A40,Sheet4!A:Q,13,FALSE) -> 30.87 | E40: =VLOOKUP(A40,Sheet4!A:C,3,FALSE) -> 78.0 | F40: =VLOOKUP(A40,Sheet4!A:F,6,FALSE) -> 64.62 | G40: =VLOOKUP(A40,Sheet6!A:D,4,FALSE) -> 20.6 | H40: =VLOOKUP(A40,Sheet4!A:H,8,FALSE) -> 110.59 | I40: 628600 | J40: 94 | K40: 124 | L40: 1 | M40: 1 | N40: 118.49527 | O40: 32.18249 | P40: 3 | Q40: 4 | R40: 1 | S40: 1 | T40: 1 | U40: 0 | V40: 1 | W40: 0 | X40: 0 | Y40: 0 | Z40: 0 | AA40: 0 | AB40: 0 | AC40: 0 | AD40: 0 | AE40: 0 | AF40: 0 | AG40: 0 | AH40: 0 | AI40: 0 | AJ40: 0 | AK40: 0 | AL40: 0 | AM40: 0 | AN40: 0 | AO40: 0 | AP40: 0 | AQ40: 0 | AR40: 0 | AS40: 1728 | AT40: 650000 | AU40: 0 | AV40: 7800 | AW40: 65 | AX40: 95 | AY40: 0 | AZ40: 0
...

Sheet Sheet7
A1: 2-22020年全国城市人口和建设用地(按城市分列)
A2: NationalUrbanPopulationandConstructionLandbyCity(2020)
A3: 面积计量单位:平方公里
A4: 人口计量单位:万人
A5: AreaMeasurementUnit:SquareKilometer
A6: PopulationMeasurementUnit:10,000persons
A7: 城市名称 Nameof Cities | B7: 市区面积 Urban District Area | C7: 市区人口 Urban District Population | D7: 市区暂住 人 口 Urban District Temporary Population | E7: 城区面积 Urban Area | F7: 城区人口 Urban Population | G7: 城区暂住 人 口 Urban Temporary Population | H7: 建成区 面 积 Area of Built District | I7: 城市建设用地面积 Area of Urban Construction Land | R7: 本年征用 土地面积 Area of Land Requisition This Year | T7: 城市名称 Name of Cities
I8: 小 计 Subtotal | J8: 居住用地 Residen- tial | K8: 公共管理与 公共服务用地 Administr- ation and Public Services | L8: 商业服务业 设施用地 Commercial and Business Facilities | M8: 工业用地 Indust- rial, Manufac- turing | N8: 物流仓储 用 地 Logistics and Warehouse | O8: 道路交通 设施用地 Road, Street and Transpor- tation | P8: 公用设施 用 地 Municipal Utilities | Q8: 绿地与 广场用地 Green Space and Square | S8: 耕地 Arable Land
A9: 全国 | B9: 2322591.9 | C9: 81643.5 | D9: 12982.7 | E9: 186628.87 | F9: 44253.74 | G9: 9509.02 | H9: 60721.32 | I9: 58355.29 | J9: 18098.71 | K9: 5162.30 | L9: 4088.64 | M9: 11339.88 | N9: 1586.19 | O9: 9503.42 | P9: 1758.08 | Q9: 6818.07 | R9: 2362.38 | S9: 999.14 | T9: 全 国
A10: 北京 | C10: 2189.0 | F10: 1916.40 | T10: 北 京
A11: 天津 | B11: 11760.3 | C11: 1386.6 | E11: 2639.78 | F11: 1174.44 | H11: 1170.24 | I11: 1040.63 | J11: 289.37 | K11: 81.36 | L11: 86.80 | M11: 238.79 | N11: 51.19 | O11: 165.52 | P11: 20.36 | Q11: 107.24 | R11: 19.62 | S11: 9.65 | T11: 天 津
A12: 河北 | B12: 49498.0 | C12: 3721.8 | D12: 211.0 | E12: 6320.88 | F12: 1796.20 | G12: 154.10 | H12: 2236.46 | I12: 2067.10 | J12: 639.42 | K12: 155.68 | L12: 126.97 | M12: 234.12 | N12: 53.72 | O12: 353.26 | P12: 57.49 | Q12: 446.44 | R12: 34.60 | S12: 23.47 | T12: 河 北
A13: 石家庄 | B13: 2195.0 | C13: 502.8 | D13: 10.2 | E13: 518.81 | F13: 331.65 | G13: 4.70 | H13: 311.83 | I13: 186.84 | J13: 93.88 | K13: 20.96 | L13: 13.92 | M13: 23.29 | N13: 3.47 | O13: 12.60 | P13: 4.34 | Q13: 14.38 | R13: 4.48 | S13: 3.36 | T13: 石家庄
A14: 晋州 | B14: 619.0 | C14: 57.5 | D14: 1.0 | E14: 90.78 | F14: 13.32 | G14: 0.64 | H14: 14.83 | I14: 14.83 | J14: 4.44 | K14: 0.83 | L14: 0.80 | M14: 1.82 | N14: 0.40 | O14: 3.08 | P14: 0.10 | Q14: 3.36 | R14: 0.71 | S14: 0.47 | T14: 晋 州
A15: 新乐 | B15: 525.0 | C15: 51.7 | D15: 0.7 | E15: 45.92 | F15: 9.18 | G15: 0.37 | H15: 14.80 | I15: 14.26 | J15: 4.12 | K15: 0.97 | L15: 0.92 | M15: 0.74 | N15: 0.35 | O15: 2.77 | P15: 0.93 | Q15: 3.46 | T15: 新 乐
A16: 唐山 | B16: 3874.0 | C16: 307.2 | D16: 10.1 | E16: 293.65 | F16: 195.67 | G16: 10.07 | H16: 249.00 | I16: 240.96 | J16: 54.88 | K16: 11.79 | L16: 18.00 | M16: 38.95 | N16: 7.89 | O16: 41.58 | P16: 7.72 | Q16: 60.15 | T16: 唐 山
A17: 滦州 | B17: 1027.2 | C17: 57.4 | D17: 6.5 | E17: 140.80 | F17: 21.72 | G17: 6.40 | H17: 30.20 | I17: 30.20 | J17: 10.03 | K17: 3.21 | L17: 2.92 | M17: 0.25 | N17: 0.74 | O17: 4.65 | P17: 0.47 | Q17: 7.93 | T17: 滦 州
A18: 遵化 | B18: 1521.0 | C18: 76.8 | D18: 2.6 | E18: 85.80 | F18: 23.94 | G18: 1.96 | H18: 26.40 | I18: 26.05 | J18: 7.41 | K18: 1.10 | L18: 0.29 | M18: 2.10 | N18: 0.40 | O18: 5.26 | P18: 1.50 | Q18: 7.99 | R18: 0.38 | T18: 遵 化
A19: 迁安 | B19: 1227.0 | C19: 77.5 | D19: 4.3 | E19: 128.10 | F19: 31.90 | G19: 4.10 | H19: 45.00 | I19: 45.00 | J19: 11.88 | K19: 4.33 | L19: 4.60 | M19: 5.81 | N19: 0.22 | O19: 7.04 | P19: 0.38 | Q19: 10.74 | T19: 迁 安
A20: 秦皇岛 | B20: 2131.5 | C20: 149.2 | D20: 29.3 | E20: 290.30 | F20: 104.70 | G20: 29.34 | H20: 145.00 | I20: 141.75 | J20: 39.92 | K20: 10.15 | L20: 12.30 | M20: 15.10 | N20: 4.90 | O20: 24.38 | P20: 5.00 | Q20: 30.00 | R20: 1.94 | S20: 0.75 | T20: 秦皇岛
A21: 邯郸 | B21: 2685.7 | C21: 383.6 | D21: 22.9 | E21: 556.00 | F21: 207.73 | G21: 10.95 | H21: 189.20 | I21: 187.23 | J21: 48.27 | K21: 15.18 | L21: 9.76 | M21: 7.67 | N21: 8.36 | O21: 40.13 | P21: 6.48 | Q21: 51.38 | R21: 2.87 | S21: 2.28 | T21: 邯 郸
A22: 武安 | B22: 1806.0 | C22: 84.7 | D22: 1.9 | E22: 95.00 | F22: 24.47 | G22: 0.73 | H22: 38.60 | I22: 37.80 | J22: 10.16 | K22: 2.94 | L22: 1.69 | M22: 6.27 | N22: 0.92 | O22: 6.84 | P22: 1.12 | Q22: 7.86 | R22: 0.56 | S22: 0.39 | T22: 武 安
A23: 邢台 | B23: 994.2 | C23: 203.4 | D23: 4.2 | E23: 205.07 | F23: 75.58 | G23: 4.61 | H23: 157.05 | I23: 152.30 | J23: 50.15 | K23: 9.04 | L23: 7.80 | M23: 17.85 | N23: 2.61 | O23: 25.41 | P23: 2.49 | Q23: 36.95 | R23: 1.03 | S23: 0.88 | T23: 邢 台
A24: 南宫 | B24: 863.3 | C24: 50.9 | D24: 0.1 | E24: 53.50 | F24: 14.75 | G24: 0.47 | H24: 16.03 | I24: 16.03 | J24: 4.93 | K24: 1.05 | L24: 1.47 | M24: 1.30 | N24: 0.14 | O24: 3.38 | P24: 0.25 | Q24: 3.51 | T24: 南 宫
A25: 沙河 | B25: 999.0 | C25: 46.0 | D25: 0.1 | E25: 21.97 | F25: 10.95 | G25: 0.13 | H25: 17.74 | I25: 17.50 | J25: 6.87 | K25: 1.41 | L25: 1.01 | M25: 0.57 | N25: 0.57 | O25: 3.17 | P25: 0.94 | Q25: 2.96 | R25: 0.99 | S25: 0.02 | T25: 沙 河
A26: 保定 | B26: 2564.8 | C26: 288.4 | D26: 20.5 | E26: 359.65 | F26: 144.70 | G26: 19.33 | H26: 205.98 | I26: 198.61 | J26: 57.13 | K26: 15.35 | L26: 9.13 | M26: 38.84 | N26: 4.03 | O26: 31.87 | P26: 5.47 | Q26: 36.79 | R26: 3.92 | S26: 2.42 | T26: 保 定
A27: 涿州 | B27: 751.3 | C27: 69.9 | D27: 1.7 | E27: 181.00 | F27: 27.11 | G27: 1.12 | H27: 37.43 | I27: 37.43 | J27: 11.81 | K27: 3.91 | L27: 2.44 | M27: 5.42 | N27: 0.31 | O27: 6.80 | P27: 0.65 | Q27: 6.09 | R27: 0.77 | S27: 0.71 | T27: 涿 州
A28: 安国 | B28: 485.1 | C28: 40.4 | D28: 0.6 | E28: 31.71 | F28: 11.09 | G28: 0.48 | H28: 14.69 | I28: 13.66 | J28: 5.24 | K28: 0.71 | L28: 0.83 | M28: 0.71 | N28: 0.20 | O28: 2.91 | P28: 0.11 | Q28: 2.95 | R28: 0.90 | S28: 0.87 | T28: 安 国
A29: 高碑店 | B29: 620.0 | C29: 57.1 | D29: 1.7 | E29: 36.80 | F29: 14.34 | G29: 0.99 | H29: 21.08 | I29: 21.08 | J29: 5.13 | K29: 1.86 | L29: 1.14 | M29: 1.70 | N29: 0.27 | O29: 4.69 | P29: 1.01 | Q29: 5.28 | R29: 0.96 | S29: 0.92 | T29: 高碑店
A30: 张家口 | B30: 6963.8 | C30: 167.6 | D30: 12.5 | E30: 408.31 | F30: 90.61 | G30: 8.45 | H30: 101.80 | I30: 97.93 | J30: 23.58 | K30: 6.56 | L30: 4.10 | M30: 3.71 | N30: 1.68 | O30: 24.67 | P30: 3.53 | Q30: 30.10 | R30: 2.76 | S30: 2.24 | T30: 张家口
A31: 承德 | B31: 1252.7 | C31: 60.1 | D31: 2.9 | E31: 724.03 | F31: 54.98 | G31: 2.87 | H31: 80.06 | I31: 76.75 | J31: 19.80 | K31: 8.12 | L31: 4.71 | M31: 10.64 | N31: 1.95 | O31: 12.26 | P31: 1.47 | Q31: 17.80 | R31: 0.02 | S31: 0.02 | T31: 承 德
A32: 平泉 | B32: 3294.1 | C32: 47.4 | D32: 0.6 | E32: 26.00 | F32: 18.83 | G32: 0.48 | H32: 17.50 | I32: 17.30 | J32: 4.89 | K32: 1.17 | L32: 0.64 | M32: 0.84 | N32: 0.54 | O32: 3.63 | P32: 1.14 | Q32: 4.45 | R32: 0.94 | S32: 0.37 | T32: 平 泉
A33: 沧州 | B33: 320.0 | C33: 69.7 | D33: 10.7 | E33: 320.00 | F33: 58.60 | G33: 9.91 | H33: 87.24 | I33: 83.07 | J33: 30.81 | K33: 6.31 | L33: 3.68 | M33: 8.13 | N33: 2.12 | O33: 14.53 | P33: 1.34 | Q33: 16.15 | T33: 沧 州
A34: 泊头 | B34: 1007.0 | C34: 63.2 | D34: 0.2 | E34: 22.00 | F34: 16.84 | G34: 0.18 | H34: 20.03 | I34: 19.82 | J34: 6.63 | K34: 1.30 | L34: 1.02 | M34: 3.75 | N34: 0.18 | O34: 3.15 | P34: 0.24 | Q34: 3.55 | T34: 泊 头
A35: 任丘 | B35: 864.0 | C35: 81.6 | D35: 7.2 | E35: 74.40 | F35: 34.64 | G35: 2.23 | H35: 50.45 | I35: 50.39 | J35: 17.20 | K35: 4.59 | L35: 3.43 | M35: 4.80 | N35: 1.87 | O35: 7.58 | P35: 2.26 | Q35: 8.66 | R35: 1.69 | S35: 1.41 | T35: 任 丘
A36: 黄骅 | B36: 2202.0 | C36: 61.7 | D36: 5.9 | E36: 200.00 | F36: 15.24 | G36: 5.56 | H36: 38.20 | I36: 35.99 | J36: 6.31 | K36: 3.69 | L36: 3.72 | M36: 6.23 | N36: 0.95 | O36: 6.99 | P36: 0.61 | Q36: 7.49 | R36: 0.70 | T36: 黄 骅
A37: 河间 | B37: 1322.0 | C37: 87.9 | D37: 2.6 | E37: 69.40 | F37: 16.59 | G37: 2.09 | H37: 20.90 | I37: 20.67 | J37: 7.01 | K37: 0.90 | L37: 0.75 | M37: 1.31 | N37: 0.45 | O37: 3.87 | P37: 0.71 | Q37: 5.67 | R37: 0.74 | T37: 河 间
A38: 廊坊 | B38: 960.0 | C38: 87.9 | D38: 17.6 | E38: 292.00 | F38: 55.04 | G38: 12.86 | H38: 73.46 | I38: 73.31 | J38: 22.91 | K38: 3.96 | L38: 3.12 | M38: 7.02 | N38: 3.24 | O38: 13.55 | P38: 2.65 | Q38: 16.86 | R38: 3.21 | S38: 2.29 | T38: 廊 坊
A39: 霸州 | B39: 784.0 | C39: 66.0 | D39: 12.3 | E39: 79.00 | F39: 11.06 | G39: 4.10 | H39: 17.60 | I39: 17.51 | J39: 6.25 | K39: 0.79 | L39: 1.18 | M39: 1.32 | N39: 0.30 | O39: 2.70 | P39: 0.80 | Q39: 4.17 | R39: 2.92 | S39: 2.36 | T39: 霸 州
A40: 三河 | B40: 643.0 | C40: 75.5 | D40: 8.5 | E40: 169.00 | F40: 20.59 | G40: 1.90 | H40: 19.31 | I40: 19.31 | J40: 2.49 | K40: 3.64 | L40: 2.29 | M40: 0.40 | N40: 0.30 | O40: 4.89 | P40: 0.70 | Q40: 4.60 | T40: 三 河
...

Sheet Sheet6
A1: 2-22019年全国城市人口和建设用地(按城市分列)
A2: NationalUrbanPopulationandConstructionLandbyCity(2019)
A3: 面积计量单位:平方公里
A4: 人口计量单位:万人
A5: AreaMeasurementUnit:SquareKilometer
A6: PopulationMeasurementUnit:10,000persons
A7: 城市名称_x000D_ Nameof_x000D_ Cities | B7: 市区面积_x000D_ Urban_x000D_ District_x000D_ Area | C7: 市区人口_x000D_ Urban_x000D_ District_x000D_ Population | D7: 市区暂住_x000D_ 人 口_x000D_ Urban_x000D_ District_x000D_ Temporary_x000D_ Population | E7: 城区面积_x000D_ Urban_x000D_ Area | F7: 城区人口_x000D_ Urban_x000D_ Population | G7: 城区暂住_x000D_ 人 口_x000D_ Urban_x000D_ Temporary_x000D_ Population | H7: 建成区_x000D_ 面 积_x000D_ Area of_x000D_ Built_x000D_ District | I7: 城市建设用地面积 Area of Urban Construction Land | R7: 本年征用_x000D_ 土地面积_x000D_ Area of_x000D_ Land_x000D_ Requisition_x000D_ This Year | T7: 城市名称_x000D_ Name of_x000D_ Cities
I8: 小计_x000D_ Subtotal | J8: 居住用地_x000D_ Residen-_x000D_ tial | K8: 公共管理与_x000D_ 公共服务用地_x000D_ Administr-_x000D_ ation and_x000D_ Public_x000D_ Services | L8: 商业服务业_x000D_ 设施用地_x000D_ Commercial_x000D_ and_x000D_ Business_x000D_ Facilities | M8: 工业用地_x000D_ Indust-_x000D_ rial,_x000D_ Manufac-_x000D_ turing | N8: 物流仓储_x000D_ 用 地_x000D_ Logistics_x000D_ and_x000D_ Warehouse | O8: 道路交通_x000D_ 设施用地_x000D_ Road,_x000D_ Street and_x000D_ Transpo-_x000D_ rtation | P8: 公用设施_x000D_ 用 地_x000D_ Municipal_x000D_ Utilities | Q8: 绿地与_x000D_ 广场用地_x000D_ Green_x000D_ Space_x000D_ and_x000D_ Square | S8: 耕地_x000D_ Arable_x000D_ Land
A9: 全国 | B9: 2281507.7 | C9: 80007.8 | D9: 12437.2 | E9: 200569.51 | F9: 43503.66 | G9: 8911.94 | H9: 60312.45 | I9: 58307.71 | J9: 18102.07 | K9: 5221.26 | L9: 4039.15 | M9: 11478.80 | N9: 1650.53 | O9: 9328.65 | P9: 1823.09 | Q9: 6664.16 | R9: 2684.81 | S9: 1189.27 | T9: 全 国
A10: 北京 | B10: 16410.0 | C10: 2153.6 | E10: 16410.00 | F10: 1865.00 | H10: 1469.05 | I10: 1471.75 | J10: 427.92 | K10: 173.14 | L10: 137.26 | M10: 263.09 | N10: 50.88 | O10: 271.62 | P10: 31.60 | Q10: 116.24 | R10: 29.90 | S10: 6.12 | T10: 北 京
A11: 天津 | B11: 11760.2 | C11: 1561.9 | E11: 2639.78 | F11: 1303.84 | H11: 1151.05 | I11: 998.15 | J11: 263.32 | K11: 75.82 | L11: 79.51 | M11: 237.71 | N11: 55.22 | O11: 151.92 | P11: 20.16 | Q11: 114.49 | R11: 13.46 | S11: 5.64 | T11: 天 津
A12: 河北 | B12: 48656.1 | C12: 3634.1 | D12: 210.7 | E12: 6309.33 | F12: 1783.36 | G12: 149.04 | H12: 2182.09 | I12: 1899.89 | J12: 614.67 | K12: 150.06 | L12: 121.26 | M12: 257.55 | N12: 54.62 | O12: 314.55 | P12: 57.71 | Q12: 329.47 | R12: 106.54 | S12: 67.19 | T12: 河 北
A13: 石家庄 | B13: 2194.1 | C13: 498.9 | D13: 9.7 | E13: 518.81 | F13: 332.32 | G13: 4.44 | H13: 309.32 | I13: 56.93 | J13: 19.31 | K13: 4.24 | L13: 2.99 | M13: 6.82 | N13: 1.28 | O13: 9.86 | P13: 2.42 | Q13: 10.01 | R13: 6.72 | S13: 4.10 | T13: 石家庄
A14: 晋州 | B14: 619.0 | C14: 57.7 | D14: 1.1 | E14: 90.78 | F14: 13.37 | G14: 0.59 | H14: 14.83 | I14: 14.83 | J14: 4.20 | K14: 1.17 | L14: 1.00 | M14: 2.30 | N14: 0.86 | O14: 3.30 | P14: 0.50 | Q14: 1.50 | R14: 1.02 | S14: 0.72 | T14: 晋 州
A15: 新乐 | B15: 525.0 | C15: 51.6 | D15: 0.6 | E15: 45.92 | F15: 9.12 | G15: 0.32 | H15: 14.01 | I15: 14.01 | J15: 4.12 | K15: 0.97 | L15: 0.92 | M15: 0.74 | N15: 0.35 | O15: 2.59 | P15: 0.93 | Q15: 3.39 | T15: 新 乐
A16: 唐山 | B16: 3874.0 | C16: 307.2 | D16: 10.1 | E16: 293.65 | F16: 195.67 | G16: 10.07 | H16: 249.00 | I16: 240.96 | J16: 61.53 | K16: 10.86 | L16: 17.00 | M16: 43.77 | N16: 4.35 | O16: 41.58 | P16: 8.35 | Q16: 53.52 | T16: 唐 山
A17: 滦州 | B17: 1027.2 | C17: 57.4 | D17: 6.5 | E17: 140.80 | F17: 21.20 | G17: 6.50 | H17: 30.10 | I17: 30.07 | J17: 10.03 | K17: 3.21 | L17: 2.92 | M17: 0.43 | N17: 0.74 | O17: 4.63 | P17: 0.47 | Q17: 7.64 | T17: 滦 州
A18: 遵化 | B18: 1521.0 | C18: 76.8 | D18: 2.6 | E18: 85.80 | F18: 22.38 | G18: 1.96 | H18: 26.40 | I18: 26.03 | J18: 7.41 | K18: 1.11 | L18: 0.29 | M18: 2.20 | N18: 0.40 | O18: 5.13 | P18: 1.50 | Q18: 7.99 | R18: 0.38 | T18: 遵 化
A19: 迁安 | B19: 1227.0 | C19: 77.4 | D19: 4.3 | E19: 128.10 | F19: 31.70 | G19: 3.60 | H19: 44.40 | I19: 42.57 | J19: 11.85 | K19: 3.84 | L19: 4.34 | M19: 8.01 | N19: 0.22 | O19: 5.49 | P19: 0.28 | Q19: 8.54 | T19: 迁 安
A20: 秦皇岛 | B20: 2131.5 | C20: 146.0 | D20: 29.0 | E20: 330.25 | F20: 103.04 | G20: 28.96 | H20: 141.80 | I20: 138.65 | J20: 39.00 | K20: 10.00 | L20: 12.00 | M20: 15.00 | N20: 4.80 | O20: 23.87 | P20: 4.98 | Q20: 29.00 | R20: 2.58 | S20: 1.68 | T20: 秦皇岛
A21: 邯郸 | B21: 2652.2 | C21: 378.9 | D21: 22.5 | E21: 556.00 | F21: 206.85 | G21: 11.03 | H21: 187.69 | I21: 197.18 | J21: 76.56 | K21: 26.58 | L21: 15.61 | M21: 15.91 | N21: 13.20 | O21: 24.33 | P21: 7.33 | Q21: 17.66 | R21: 6.26 | S21: 4.90 | T21: 邯 郸
A22: 武安 | B22: 1806.0 | C22: 84.9 | D22: 1.9 | E22: 95.00 | F22: 24.17 | G22: 0.72 | H22: 37.30 | I22: 37.30 | J22: 11.50 | K22: 2.74 | L22: 1.47 | M22: 8.84 | N22: 1.85 | O22: 6.40 | P22: 1.08 | Q22: 3.42 | R22: 0.68 | S22: 0.41 | T22: 武 安
A23: 邢台 | B23: 132.3 | C23: 91.5 | D23: 3.0 | E23: 114.80 | F23: 57.14 | G23: 3.01 | H23: 108.19 | I23: 108.19 | J23: 42.66 | K23: 7.73 | L23: 6.44 | M23: 17.13 | N23: 2.36 | O23: 20.15 | P23: 2.23 | Q23: 9.49 | R23: 39.77 | S23: 27.43 | T23: 邢 台
A24: 南宫 | B24: 863.3 | C24: 50.9 | D24: 0.1 | E24: 53.50 | F24: 14.60 | G24: 0.57 | H24: 16.03 | I24: 16.03 | J24: 4.93 | K24: 1.45 | L24: 1.68 | M24: 3.22 | N24: 0.14 | O24: 2.91 | P24: 0.25 | Q24: 1.45 | T24: 南 宫
A25: 沙河 | B25: 999.0 | C25: 46.0 | D25: 0.1 | E25: 21.97 | F25: 9.24 | G25: 0.13 | H25: 17.74 | I25: 17.50 | J25: 4.37 | K25: 1.41 | L25: 1.01 | M25: 3.04 | N25: 0.57 | O25: 0.70 | P25: 0.94 | Q25: 5.46 | R25: 0.06 | S25: 0.02 | T25: 沙 河
A26: 保定 | B26: 2564.8 | C26: 289.0 | D26: 21.4 | E26: 344.93 | F26: 145.07 | G26: 20.46 | H26: 199.35 | I26: 192.78 | J26: 67.53 | K26: 15.98 | L26: 9.63 | M26: 48.05 | N26: 4.49 | O26: 25.56 | P26: 5.83 | Q26: 15.71 | R26: 3.97 | S26: 1.86 | T26: 保 定
A27: 涿州 | B27: 751.3 | C27: 70.4 | D27: 0.7 | E27: 181.00 | F27: 27.38 | G27: 0.58 | H27: 36.34 | I27: 36.34 | J27: 11.49 | K27: 3.90 | L27: 2.10 | M27: 5.15 | N27: 0.31 | O27: 6.78 | P27: 0.65 | Q27: 5.96 | T27: 涿 州
A28: 安国 | B28: 485.1 | C28: 41.2 | D28: 0.3 | E28: 31.71 | F28: 11.24 | G28: 0.30 | H28: 14.68 | I28: 13.49 | J28: 5.24 | K28: 0.71 | L28: 0.83 | M28: 0.71 | N28: 0.20 | O28: 2.87 | P28: 0.11 | Q28: 2.82 | R28: 0.38 | S28: 0.37 | T28: 安 国
A29: 高碑店 | B29: 620.0 | C29: 57.0 | D29: 1.7 | E29: 36.80 | F29: 14.02 | G29: 0.97 | H29: 20.58 | I29: 20.58 | J29: 5.20 | K29: 1.86 | L29: 1.14 | M29: 1.70 | N29: 0.27 | O29: 4.69 | P29: 1.01 | Q29: 4.71 | R29: 0.96 | S29: 0.92 | T29: 高碑店
A30: 白沟新城 | B30: 54.4 | C30: 6.0 | D30: 3.7 | E30: 54.35 | F30: 5.61 | G30: 3.70 | H30: 19.85 | I30: 18.42 | J30: 7.38 | K30: 0.59 | L30: 3.50 | M30: 3.42 | N30: 0.26 | O30: 2.50 | P30: 0.31 | Q30: 0.46 | R30: 0.59 | S30: 0.41 | T30: 白沟新城
A31: 张家口 | B31: 6963.8 | C31: 198.5 | D31: 15.8 | E31: 407.45 | F31: 102.44 | G31: 6.58 | H31: 100.94 | I31: 97.07 | J31: 25.57 | K31: 7.68 | L31: 4.38 | M31: 6.01 | N31: 1.68 | O31: 21.26 | P31: 3.63 | Q31: 26.86 | R31: 2.10 | S31: 0.44 | T31: 张家口
A32: 承德 | B32: 1252.7 | C32: 60.1 | D32: 2.0 | E32: 724.03 | F32: 55.12 | G32: 2.03 | H32: 78.02 | I32: 74.39 | J32: 18.89 | K32: 7.88 | L32: 4.42 | M32: 10.61 | N32: 1.92 | O32: 11.41 | P32: 1.46 | Q32: 17.80 | R32: 1.90 | S32: 1.00 | T32: 承 德
A33: 平泉 | B33: 3294.1 | C33: 48.0 | D33: 0.8 | E33: 26.00 | F33: 16.95 | G33: 0.62 | H33: 17.30 | I33: 17.10 | J33: 4.89 | K33: 1.07 | L33: 0.66 | M33: 0.92 | N33: 0.54 | O33: 3.63 | P33: 1.14 | Q33: 4.25 | R33: 0.94 | S33: 0.37 | T33: 平 泉
A34: 沧州 | B34: 320.0 | C34: 68.7 | D34: 8.6 | E34: 320.00 | F34: 57.67 | G34: 8.09 | H34: 87.24 | I34: 83.07 | J34: 30.81 | K34: 6.31 | L34: 3.68 | M34: 11.40 | N34: 2.12 | O34: 14.53 | P34: 1.34 | Q34: 12.88 | R34: 3.58 | S34: 2.39 | T34: 沧 州
A35: 泊头 | B35: 1007.0 | C35: 63.2 | D35: 0.2 | E35: 22.00 | F35: 16.89 | G35: 0.20 | H35: 20.03 | I35: 19.82 | J35: 6.63 | K35: 1.30 | L35: 1.02 | M35: 3.75 | N35: 0.18 | O35: 3.15 | P35: 0.24 | Q35: 3.55 | T35: 泊 头
A36: 任丘 | B36: 864.0 | C36: 81.0 | D36: 7.2 | E36: 74.40 | F36: 34.63 | G36: 2.23 | H36: 49.40 | I36: 49.33 | J36: 17.03 | K36: 4.56 | L36: 3.42 | M36: 4.80 | N36: 1.67 | O36: 7.44 | P36: 2.20 | Q36: 8.21 | R36: 1.37 | S36: 1.04 | T36: 任 丘
A37: 黄骅 | B37: 2202.0 | C37: 61.2 | D37: 5.7 | E37: 200.00 | F37: 15.04 | G37: 5.46 | H37: 37.50 | I37: 35.31 | J37: 10.00 | K37: 3.68 | L37: 1.70 | M37: 5.22 | N37: 0.94 | O37: 6.25 | P37: 0.60 | Q37: 6.92 | R37: 0.20 | T37: 黄 骅
A38: 河间 | B38: 1322.0 | C38: 87.8 | D38: 3.0 | E38: 69.40 | F38: 16.12 | G38: 2.06 | H38: 20.90 | I38: 20.72 | J38: 7.01 | K38: 0.90 | L38: 0.75 | M38: 1.31 | N38: 0.45 | O38: 3.61 | P38: 0.71 | Q38: 5.98 | R38: 2.32 | T38: 河 间
A39: 廊坊 | B39: 960.0 | C39: 87.9 | D39: 18.6 | E39: 292.00 | F39: 53.02 | G39: 11.05 | H39: 71.37 | I39: 71.17 | J39: 23.71 | K39: 3.96 | L39: 3.12 | M39: 7.36 | N39: 3.24 | O39: 13.63 | P39: 2.65 | Q39: 13.50 | R39: 18.31 | S39: 9.90 | T39: 廊 坊
A40: 霸州 | B40: 784.0 | C40: 65.8 | D40: 12.6 | E40: 79.00 | F40: 10.41 | G40: 3.80 | H40: 17.60 | I40: 17.51 | J40: 8.40 | K40: 0.79 | L40: 1.18 | M40: 1.32 | N40: 0.30 | O40: 2.63 | P40: 0.80 | Q40: 2.09 | R40: 1.27 | S40: 1.10 | T40: 霸 州
...

Sheet Sheet2
B1: gdp | C1: region | D1: green_rate | E1: c_population | F1: c_area | G1: c_water_resources
A2: 三亚 | B2: 835.37 | C2: 5 | D2: 42.34 | E2: 73 | F2: 52 | G2: 158392
A3: 上海 | B3: 43214.85 | C3: 2 | D3: 37.32 | E3: 2222 | F3: 1238 | G3: 585700
A4: 上饶 | B4: 3043.5 | C4: 2 | D4: 48.91 | E4: 353 | F4: 103 | G4: 3079500
A5: 东莞 | B5: 10855.35 | C5: 5 | D5: 46 | E5: 966 | F5: 1007.76 | G5: 200195
A6: 中山 | B6: 3566.17 | C6: 5 | D6: 43.14 | E6: 385 | F6: 166.5 | G6: 155800
A7: 临沂 | B7: 5465.5 | C7: 2 | D7: 42.12 | E7: 607 | F7: 259 | G7: 908700
A8: 丹东 | B8: 854.4 | C8: 0 | D8: 41 | E8: 150 | F8: 75 | G8: 1115000
A9: 丹阳 | B9: 346.22 | C9: 2 | D9: 19.99 | E9: 98.89 | F9: 33.2 | G9: 1264900
A10: 义乌 | B10: 1730.16 | C10: 2 | D10: 25.86 | E10: 131.86 | F10: 196.1 | G10: 82000
A11: 乌鲁木齐 | B11: 3691.57 | C11: 3 | D11: 40.54 | E11: 350.58 | F11: 522 | G11: 110521
A12: 九江 | B12: 3735.7 | C12: 2 | D12: 48.83 | E12: 281 | F12: 158 | G12: 2005400
A13: 佛山 | B13: 12156.54 | C13: 5 | D13: 36.3 | E13: 906 | F13: 161.25 | G13: 296300
... A136: 黄石 | B136: 1910 | C136: 6 | D136: 40.42 | E136: 163 | F136: 84 | G136: 616862

Sheet Sheet4
A1: 2-22021年全国城市人口和建设用地(按城市分列)
A2: NationalUrbanPopulationandConstructionLandbyCity(2021)
A3: 面积计量单位:平方公里
A4: 人口计量单位:万人
A5: AreaMeasurementUnit:SquareKilometer
A6: PopulationMeasurementUnit:10,000persons
A7: 城市名称 Nameof Cities | B7: 市区面积 Urban District Area | C7: 市区人口 Urban District Population | D7: 市区暂住 人 口 Urban District Temporary Population | E7: 城区面积 Urban Area | F7: 城区人口 Urban Population | G7: 城区暂住 人 口 Urban Temporary Population | H7: 建成区 面 积 Area of Built District | I7: 城市建设用地面积 Area of Urban Construction Land | R7: 本年征用 土地面积 Area of Land Requisition This Year | T7: 城市名称 Name of Cities
I8: 小 计 Subtotal | J8: 居住用地 Residen- tial | K8: 公共管理与 公共服务用地 Administr- ation and Public Services | L8: 商业服务业 设施用地 Commercial and Business Facilities | M8: 工业用地 Indust- rial, Manufac- turing | N8: 物流仓储 用 地 Logistics and Warehouse | O8: 道路交通 设施用地 Road, Street and Transpor- tation | P8: 公用设施 用 地 Municipal Utilities | Q8: 绿地与 广场用地 Green Space and Square | S8: 耕地 Arable Land
A9: 全国 | B9: 2368544.5 | C9: 83733.0 | D9: 13584.7 | E9: 188300.45 | F9: 45747.87 | G9: 10180.09 | H9: 62420.53 | I9: 59424.59 | J9: 18617.91 | K9: 5248.92 | L9: 4264.06 | M9: 11336.75 | N9: 1575.87 | O9: 10060.61 | P9: 1551.02 | Q9: 6769.45 | R9: 1902.24 | S9: 827.92 | T9: 全 国
A10: 北京 | C10: 2188.6 | F10: 1916.10 | T10: 北 京
A11: 天津 | B11: 11926.3 | C11: 1373.0 | E11: 2653.42 | F11: 1165.40 | H11: 1237.33 | I11: 1079.25 | J11: 302.25 | K11: 86.52 | L11: 93.27 | M11: 256.54 | N11: 51.90 | O11: 167.64 | P11: 19.61 | Q11: 101.52 | R11: 10.64 | S11: 5.17 | T11: 天 津
A12: 河北 | B12: 49498.0 | C12: 3778.9 | D12: 220.2 | E12: 6324.00 | F12: 1817.68 | G12: 182.17 | H12: 2278.90 | I12: 2229.97 | J12: 678.12 | K12: 167.27 | L12: 150.64 | M12: 241.12 | N12: 67.55 | O12: 411.92 | P12: 58.03 | Q12: 455.32 | R12: 47.57 | S12: 31.85 | T12: 河 北
A13: 石家庄 | B13: 2195.0 | C13: 569.0 | D13: 11.3 | E13: 518.81 | F13: 361.67 | G13: 5.18 | H13: 334.77 | I13: 331.93 | J13: 127.64 | K13: 33.94 | L13: 37.04 | M13: 27.38 | N13: 18.57 | O13: 62.34 | P13: 5.90 | Q13: 19.12 | R13: 3.20 | S13: 2.05 | T13: 石家庄
A14: 晋州 | B14: 619.0 | C14: 57.3 | D14: 1.1 | E14: 90.78 | F14: 13.34 | G14: 0.62 | H14: 14.83 | I14: 14.83 | J14: 4.44 | K14: 0.83 | L14: 0.80 | M14: 1.62 | N14: 0.40 | O14: 3.18 | P14: 0.10 | Q14: 3.46 | R14: 0.28 | S14: 0.17 | T14: 晋 州
A15: 新乐 | B15: 525.0 | C15: 47.9 | D15: 0.7 | E15: 45.92 | F15: 9.18 | G15: 0.37 | H15: 14.80 | I15: 14.26 | J15: 4.12 | K15: 0.97 | L15: 0.92 | M15: 0.74 | N15: 0.35 | O15: 2.77 | P15: 0.92 | Q15: 3.47 | T15: 新 乐
A16: 唐山 | B16: 3874.0 | C16: 307.2 | D16: 10.1 | E16: 293.65 | F16: 195.67 | G16: 10.07 | H16: 249.00 | I16: 240.96 | J16: 54.88 | K16: 11.79 | L16: 18.00 | M16: 37.24 | N16: 7.89 | O16: 42.22 | P16: 7.72 | Q16: 61.22 | T16: 唐 山
A17: 滦州 | B17: 1027.2 | C17: 52.0 | D17: 6.5 | E17: 140.80 | F17: 21.73 | G17: 6.40 | H17: 30.25 | I17: 30.25 | J17: 10.04 | K17: 3.21 | L17: 2.92 | M17: 0.25 | N17: 0.74 | O17: 4.67 | P17: 0.47 | Q17: 7.95 | T17: 滦 州
A18: 遵化 | B18: 1521.0 | C18: 75.4 | D18: 2.6 | E18: 85.80 | F18: 24.72 | G18: 2.15 | H18: 26.70 | I18: 26.11 | J18: 7.41 | K18: 1.10 | L18: 0.28 | M18: 2.10 | N18: 0.40 | O18: 5.35 | P18: 1.48 | Q18: 7.99 | R18: 0.38 | T18: 遵 化
A19: 迁安 | B19: 1227.0 | C19: 77.5 | D19: 4.3 | E19: 128.10 | F19: 31.90 | G19: 4.10 | H19: 45.10 | I19: 45.10 | J19: 11.66 | K19: 4.35 | L19: 4.63 | M19: 5.83 | N19: 0.22 | O19: 7.29 | P19: 0.38 | Q19: 10.74 | R19: 1.07 | S19: 0.61 | T19: 迁 安
A20: 秦皇岛 | B20: 2131.5 | C20: 150.1 | D20: 32.1 | E20: 290.30 | F20: 105.43 | G20: 33.15 | H20: 146.70 | I20: 143.45 | J20: 40.09 | K20: 10.23 | L20: 12.35 | M20: 15.60 | N20: 4.92 | O20: 24.80 | P20: 5.02 | Q20: 30.44 | R20: 5.91 | S20: 4.12 | T20: 秦皇岛
A21: 邯郸 | B21: 2685.7 | C21: 383.2 | D21: 15.2 | E21: 556.00 | F21: 200.14 | G21: 13.52 | H21: 192.20 | I21: 190.25 | J21: 47.33 | K21: 13.78 | L21: 8.13 | M21: 11.47 | N21: 8.51 | O21: 42.66 | P21: 6.29 | Q21: 52.08 | R21: 2.74 | S21: 2.16 | T21: 邯 郸
A22: 武安 | B22: 1806.0 | C22: 84.1 | D22: 1.9 | E22: 95.00 | F22: 24.54 | G22: 0.72 | H22: 39.30 | I22: 38.60 | J22: 10.71 | K22: 3.06 | L22: 1.71 | M22: 6.28 | N22: 0.88 | O22: 6.92 | P22: 1.14 | Q22: 7.90 | R22: 4.10 | S22: 3.25 | T22: 武 安
A23: 邢台 | B23: 994.2 | C23: 208.3 | D23: 3.6 | E23: 205.07 | F23: 75.99 | G23: 3.53 | H23: 157.05 | I23: 151.08 | J23: 51.27 | K23: 9.26 | L23: 8.11 | M23: 17.92 | N23: 2.60 | O23: 25.70 | P23: 2.49 | Q23: 33.73 | R23: 1.03 | S23: 0.88 | T23: 邢 台
A24: 南宫 | B24: 863.3 | C24: 50.5 | D24: 0.1 | E24: 53.50 | F24: 14.70 | G24: 0.12 | H24: 16.03 | I24: 16.03 | J24: 4.94 | K24: 1.05 | L24: 1.34 | M24: 1.30 | N24: 0.14 | O24: 3.49 | P24: 0.25 | Q24: 3.52 | T24: 南 宫
A25: 沙河 | B25: 999.0 | C25: 46.0 | D25: 0.1 | E25: 21.97 | F25: 10.95 | G25: 0.13 | H25: 17.96 | I25: 17.72 | J25: 7.96 | K25: 1.56 | L25: 1.37 | M25: 0.57 | N25: 0.06 | O25: 3.17 | P25: 0.07 | Q25: 2.96 | R25: 2.41 | S25: 1.22 | T25: 沙 河
A26: 保定 | B26: 2564.8 | C26: 289.7 | D26: 43.5 | E26: 359.65 | F26: 145.60 | G26: 42.18 | H26: 206.53 | I26: 199.72 | J26: 57.62 | K26: 15.50 | L26: 9.25 | M26: 38.83 | N26: 4.01 | O26: 32.23 | P26: 5.47 | Q26: 36.81 | R26: 4.07 | S26: 2.51 | T26: 保 定
A27: 涿州 | B27: 751.3 | C27: 69.8 | D27: 0.6 | E27: 181.00 | F27: 26.96 | G27: 0.16 | H27: 37.56 | I27: 37.56 | J27: 11.81 | K27: 3.91 | L27: 2.44 | M27: 5.42 | N27: 0.31 | O27: 6.93 | P27: 0.65 | Q27: 6.09 | R27: 1.68 | S27: 1.51 | T27: 涿 州
A28: 安国 | B28: 485.1 | C28: 40.4 | D28: 0.6 | E28: 31.71 | F28: 11.07 | G28: 0.52 | H28: 14.69 | I28: 14.63 | J28: 5.24 | K28: 0.71 | L28: 0.83 | M28: 0.71 | N28: 0.20 | O28: 3.86 | P28: 0.11 | Q28: 2.97 | R28: 0.92 | S28: 0.88 | T28: 安 国
A29: 高碑店 | B29: 620.0 | C29: 57.1 | D29: 1.7 | E29: 36.80 | F29: 14.34 | G29: 0.99 | H29: 21.08 | I29: 21.08 | J29: 5.10 | K29: 1.86 | L29: 1.14 | M29: 1.70 | N29: 0.27 | O29: 4.69 | P29: 1.01 | Q29: 5.31 | R29: 0.45 | S29: 0.24 | T29: 高碑店
A30: 张家口 | B30: 6963.8 | C30: 154.9 | D30: 8.5 | E30: 411.43 | F30: 90.78 | G30: 9.78 | H30: 101.80 | I30: 97.96 | J30: 23.39 | K30: 6.56 | L30: 4.05 | M30: 3.71 | N30: 1.68 | O30: 24.86 | P30: 3.53 | Q30: 30.18 | R30: 4.18 | S30: 3.07 | T30: 张家口
A31: 承德 | B31: 1252.7 | C31: 60.1 | D31: 3.1 | E31: 724.03 | F31: 55.02 | G31: 3.13 | H31: 81.00 | I31: 77.33 | J31: 19.87 | K31: 8.20 | L31: 4.73 | M31: 10.75 | N31: 1.98 | O31: 12.41 | P31: 1.47 | Q31: 17.92 | R31: 0.41 | S31: 0.05 | T31: 承 德
A32: 平泉 | B32: 3294.1 | C32: 47.3 | D32: 0.5 | E32: 26.00 | F32: 18.84 | G32: 0.48 | H32: 17.60 | I32: 17.40 | J32: 4.94 | K32: 1.17 | L32: 0.64 | M32: 0.84 | N32: 0.54 | O32: 3.68 | P32: 1.14 | Q32: 4.45 | R32: 0.94 | S32: 0.37 | T32: 平 泉
A33: 沧州 | B33: 320.0 | C33: 70.6 | D33: 12.5 | E33: 320.00 | F33: 59.43 | G33: 11.64 | H33: 89.71 | I33: 85.44 | J33: 30.81 | K33: 6.31 | L33: 4.75 | M33: 8.13 | N33: 2.12 | O33: 15.05 | P33: 1.34 | Q33: 16.93 | R33: 2.47 | S33: 1.74 | T33: 沧 州
A34: 泊头 | B34: 1007.0 | C34: 62.3 | D34: 0.4 | E34: 22.00 | F34: 16.84 | G34: 0.17 | H34: 20.15 | I34: 19.94 | J34: 6.75 | K34: 1.30 | L34: 1.02 | M34: 3.63 | N34: 0.18 | O34: 3.15 | P34: 0.24 | Q34: 3.67 | R34: 0.12 | S34: 0.08 | T34: 泊 头
A35: 任丘 | B35: 864.0 | C35: 81.6 | D35: 7.2 | E35: 74.40 | F35: 34.65 | G35: 2.23 | H35: 51.45 | I35: 51.39 | J35: 17.35 | K35: 4.86 | L35: 3.53 | M35: 4.81 | N35: 1.87 | O35: 7.75 | P35: 2.36 | Q35: 8.86 | R35: 1.05 | S35: 0.71 | T35: 任 丘
A36: 黄骅 | B36: 2202.0 | C36: 62.9 | D36: 6.3 | E36: 200.00 | F36: 15.94 | G36: 5.86 | H36: 38.20 | I36: 35.38 | J36: 6.31 | K36: 2.74 | L36: 3.72 | M36: 6.23 | N36: 0.95 | O36: 7.26 | P36: 0.61 | Q36: 7.56 | R36: 1.00 | T36: 黄 骅
A37: 河间 | B37: 1322.0 | C37: 88.0 | D37: 1.9 | E37: 69.40 | F37: 14.03 | G37: 0.90 | H37: 20.90 | I37: 20.38 | J37: 7.01 | K37: 0.80 | L37: 0.62 | M37: 1.19 | N37: 0.40 | O37: 3.97 | P37: 0.63 | Q37: 5.76 | R37: 0.38 | T37: 河 间
A38: 廊坊 | B38: 960.0 | C38: 88.7 | D38: 12.2 | E38: 292.00 | F38: 56.06 | G38: 10.62 | H38: 80.12 | I38: 79.39 | J38: 25.21 | K38: 4.02 | L38: 3.52 | M38: 7.63 | N38: 3.24 | O38: 14.80 | P38: 2.65 | Q38: 18.32 | R38: 3.99 | S38: 2.87 | T38: 廊 坊
A39: 霸州 | B39: 784.0 | C39: 65.9 | D39: 11.5 | E39: 79.00 | F39: 11.10 | G39: 4.05 | H39: 17.60 | I39: 17.51 | J39: 6.25 | K39: 0.79 | L39: 1.18 | M39: 1.32 | N39: 0.30 | O39: 2.70 | P39: 0.80 | Q39: 4.17 | R39: 1.78 | S39: 1.21 | T39: 霸 州
A40: 三河 | B40: 643.0 | C40: 77.0 | D40: 8.5 | E40: 169.00 | F40: 20.89 | G40: 2.00 | H40: 19.31 | I40: 19.31 | J40: 2.49 | K40: 3.64 | L40: 2.29 | M40: 0.40 | N40: 0.30 | O40: 4.89 | P40: 0.70 | Q40: 4.60 | T40: 三 河
...
